Workbook

Sheet README
A1: NFL Predictor Betting Template (Decision Support)
A3: How to use:
A4: 1) Paste live moneylines/spread/total into the *Live* columns.
A5: 2) Recommendations update automatically (edges/actions).
A6: 3) Convert to .xlsb via Excel Save As if desired.
A8: Notes:
A9: - Market raw prob is implied from a single offered line (includes vig). No-vig re-normalizes home/away to sum to 1.
A10: - Action thresholds: PASS <2%, LEAN <4%, SMALL <7%, MEDIUM <10%, STRONG >=10%.
A11: - Live recommendations use live odds + model probabilities. Spread/total cover probs are approximated from point predictions (mu) and p10/p90 quantiles (sigma) when available.
A12: - The Live tab is a lightweight heuristic: enter score + minutes remaining to get a state-adjusted probability/edge view. It is not a trained in-game model.

Sheet Bets
A1: season | B1: week | C1: date | D1: gametime | E1: game_datetime | F1: game_id | G1: away_abbr | H1: home_abbr | I1: away_spread_model_input | J1: home_spread_model_input | K1: away_moneyline_model_input | L1: home_moneyline_model_input | M1: total_model_input | N1: model_away_prob | O1: model_home_prob | P1: predicted_away_score | Q1: predicted_home_score | R1: predicted_margin | S1: predicted_total | T1: predicted_margin_p10 | U1: predicted_margin_p50 | V1: predicted_margin_p90 | W1: predicted_total_p10 | X1: predicted_total_p50 | Y1: predicted_total_p90 | Z1: away_spread_live | AA1: away_spread_odds_live | AB1: home_spread_live | AC1: home_spread_odds_live | AD1: away_moneyline_live | AE1: home_moneyline_live | AF1: total_live | AG1: total_over_odds_live | AH1: total_under_odds_live | AI1: spread_edge_points_home | AJ1: market_away_prob_raw | AK1: market_home_prob_raw | AL1: market_away_prob_novig | AM1: market_home_prob_novig | AN1: edge_away_prob | AO1: edge_home_prob | AP1: spread_value_side | AQ1: spread_edge_prob | AR1: spread_action | AS1: spread_confidence_1_10 | AT1: spread_ev | AU1: money_value_side | AV1: money_edge_prob | AW1: money_action | AX1: money_confidence_1_10 | AY1: moneyline_ev | AZ1: total_value_side | BA1: total_edge_prob | BB1: total_action | BC1: total_confidence_1_10 | BD1: total_ev | BE1: spread_mu_margin | BF1: spread_sigma_margin | BG1: spread_p_home_cover | BH1: spread_p_away_cover | BI1: spread_implied_home_prob | BJ1: spread_implied_away_prob | BK1: spread_edge_home | BL1: spread_edge_away | BM1: total_mu | BN1: total_sigma | BO1: total_p_over | BP1: total_p_under | BQ1: total_implied_over_prob | BR1: total_implied_under_prob | BS1: total_edge_over | BT1: total_edge_under
A2: 2026 | B2: 1 | C2: 2026-09-09 | D2: 20:20 | E2: 46274.847 | F2: 2026_01_NE_SEA | G2: NE | H2: SEA | I2: 3 | J2: -3 | K2: 140 | L2: -166 | M2: 44.5 | N2: 0.405 | O2: 0.595 | P2: 20.8 | Q2: 23.2 | R2: 2.4 | S2: 44.1 | T2: -14.6 | U2: 2.8 | V2: 22.6 | W2: 28.4 | X2: 43.4 | Y2: 62.9 | Z2: 3 | AA2: -110 | AB2: =-Z2 | AC2: -110 | AD2: 140 | AE2: -166 | AF2: 44.5 | AG2: -110 | AH2: -110 | AI2: =IF(OR(ISBLANK(AB2),ISBLANK(R2)),NA(),R2+AB2) | AJ2: =IF(OR(ISBLANK(AD2),AD2=0),NA(),IF(AD2>0,100/(AD2+100),-(AD2)/(-(AD2)+100))) | AK2: =IF(OR(ISBLANK(AE2),AE2=0),NA(),IF(AE2>0,100/(AE2+100),-(AE2)/(-(AE2)+100))) | AL2: =IF(OR(ISNA(AK2),ISNA(AJ2)),NA(),AJ2/(AK2+AJ2)) | AM2: =IF(OR(ISNA(AK2),ISNA(AJ2)),NA(),AK2/(AK2+AJ2)) | AN2: =N2-AL2 | AO2: =O2-AM2 | AP2: =IF(BK2>=BL2,H2,G2) | AQ2: =MAX(0,BK2,BL2) | AR2: =IF(AQ2<=0,"PASS",IF(AQ2<0.02,"PASS",IF(AQ2<0.04,"LEAN",IF(AQ2<0.07,"SMALL",IF(AQ2<0.10,"MEDIUM","STRONG"))))) | AS2: =IF(AQ2<0.01,1,IF(AQ2<0.02,2,IF(AQ2<0.03,3,IF(AQ2<0.04,4,IF(AQ2<0.05,5,IF(AQ2<0.06,6,IF(AQ2<0.07,7,IF(AQ2<0.08,8,IF(AQ2<0.10,9,10))))))))) | AT2: =IF(AP2=H2,(BG2)*(IF(AC2>0,AC2/100,100/ABS(AC2)))-(1-(BG2)),(BH2)*(IF(AA2>0,AA2/100,100/ABS(AA2)))-(1-(BH2))) | AU2: =IF((O2-AK2)>=(N2-AJ2),H2,G2) | AV2: =MAX(0,(O2-AK2),(N2-AJ2)) | AW2: =IF(AV2<=0,"PASS",IF(AV2<0.02,"PASS",IF(AV2<0.04,"LEAN",IF(AV2<0.07,"SMALL",IF(AV2<0.10,"MEDIUM","STRONG"))))) | AX2: =IF(AV2<0.01,1,IF(AV2<0.02,2,IF(AV2<0.03,3,IF(AV2<0.04,4,IF(AV2<0.05,5,IF(AV2<0.06,6,IF(AV2<0.07,7,IF(AV2<0.08,8,IF(AV2<0.10,9,10))))))))) | AY2: =IF(AU2=H2,(O2)*(IF(AE2>0,AE2/100,100/ABS(AE2)))-(1-(O2)),(N2)*(IF(AD2>0,AD2/100,100/ABS(AD2)))-(1-(N2))) | AZ2: =IF(BS2>=BT2,"OVER","UNDER") | BA2: =MAX(0,BS2,BT2) | BB2: =IF(BA2<=0,"PASS",IF(BA2<0.02,"PASS",IF(BA2<0.04,"LEAN",IF(BA2<0.07,"SMALL",IF(BA2<0.10,"MEDIUM","STRONG"))))) | BC2: =IF(BA2<0.01,1,IF(BA2<0.02,2,IF(BA2<0.03,3,IF(BA2<0.04,4,IF(BA2<0.05,5,IF(BA2<0.06,6,IF(BA2<0.07,7,IF(BA2<0.08,8,IF(BA2<0.10,9,10))))))))) | BD2: =IF(AZ2="OVER",(BO2)*(IF(AG2>0,AG2/100,100/ABS(AG2)))-(1-(BO2)),(BP2)*(IF(AH2>0,AH2/100,100/ABS(AH2)))-(1-(BP2))) | BE2: =R2 | BF2: =IF(OR(ISBLANK(T2),ISBLANK(V2)),13,(V2-T2)/(2.56310313109)) | BG2: =IF(OR(ISNA(BF2),BF2<=0,ISBLANK(AB2)),NA(),1-NORMSDIST(((-AB2)-(BE2))/(BF2))) | BH2: =IF(OR(ISNA(BF2),BF2<=0,ISBLANK(Z2)),NA(),NORMSDIST(((Z2)-(BE2))/(BF2))) | BI2: =IF(OR(ISBLANK(AC2),AC2=0),NA(),IF(AC2>0,100/(AC2+100),-(AC2)/(-(AC2)+100))) | BJ2: =IF(OR(ISBLANK(AA2),AA2=0),NA(),IF(AA2>0,100/(AA2+100),-(AA2)/(-(AA2)+100))) | BK2: =BG2-BI2 | BL2: =BH2-BJ2 | BM2: =S2 | BN2: =IF(OR(ISBLANK(W2),ISBLANK(Y2)),16,(Y2-W2)/(2.56310313109)) | BO2: =IF(OR(ISNA(BN2),BN2<=0,ISBLANK(AF2)),NA(),1-NORMSDIST(((AF2)-(BM2))/(BN2))) | BP2: =IF(ISNA(BO2),NA(),1-(BO2)) | BQ2: =IF(OR(ISBLANK(AG2),AG2=0),NA(),IF(AG2>0,100/(AG2+100),-(AG2)/(-(AG2)+100))) | BR2: =IF(OR(ISBLANK(AH2),AH2=0),NA(),IF(AH2>0,100/(AH2+100),-(AH2)/(-(AH2)+100))) | BS2: =BO2-BQ2 | BT2: =BP2-BR2
A3: 2026 | B3: 1 | C3: 2026-09-10 | D3: 20:35 | E3: 46275.858 | F3: 2026_01_SF_LA | G3: SF | H3: LAR | I3: 3.5 | J3: -3.5 | K3: 164 | L3: -198 | M3: 48.5 | N3: 0.3419 | O3: 0.6581 | P3: 20.2 | Q3: 24 | R3: 3.8 | S3: 44.1 | T3: -13.3 | U3: 3.9 | V3: 21.3 | W3: 31.8 | X3: 46.3 | Y3: 67.1 | Z3: 3.5 | AA3: -110 | AB3: =-Z3 | AC3: -110 | AD3: 164 | AE3: -198 | AF3: 48.5 | AG3: -110 | AH3: -110 | AI3: =IF(OR(ISBLANK(AB3),ISBLANK(R3)),NA(),R3+AB3) | AJ3: =IF(OR(ISBLANK(AD3),AD3=0),NA(),IF(AD3>0,100/(AD3+100),-(AD3)/(-(AD3)+100))) | AK3: =IF(OR(ISBLANK(AE3),AE3=0),NA(),IF(AE3>0,100/(AE3+100),-(AE3)/(-(AE3)+100))) | AL3: =IF(OR(ISNA(AK3),ISNA(AJ3)),NA(),AJ3/(AK3+AJ3)) | AM3: =IF(OR(ISNA(AK3),ISNA(AJ3)),NA(),AK3/(AK3+AJ3)) | AN3: =N3-AL3 | AO3: =O3-AM3 | AP3: =IF(BK3>=BL3,H3,G3) | AQ3: =MAX(0,BK3,BL3) | AR3: =IF(AQ3<=0,"PASS",IF(AQ3<0.02,"PASS",IF(AQ3<0.04,"LEAN",IF(AQ3<0.07,"SMALL",IF(AQ3<0.10,"MEDIUM","STRONG"))))) | AS3: =IF(AQ3<0.01,1,IF(AQ3<0.02,2,IF(AQ3<0.03,3,IF(AQ3<0.04,4,IF(AQ3<0.05,5,IF(AQ3<0.06,6,IF(AQ3<0.07,7,IF(AQ3<0.08,8,IF(AQ3<0.10,9,10))))))))) | AT3: =IF(AP3=H3,(BG3)*(IF(AC3>0,AC3/100,100/ABS(AC3)))-(1-(BG3)),(BH3)*(IF(AA3>0,AA3/100,100/ABS(AA3)))-(1-(BH3))) | AU3: =IF((O3-AK3)>=(N3-AJ3),H3,G3) | AV3: =MAX(0,(O3-AK3),(N3-AJ3)) | AW3: =IF(AV3<=0,"PASS",IF(AV3<0.02,"PASS",IF(AV3<0.04,"LEAN",IF(AV3<0.07,"SMALL",IF(AV3<0.10,"MEDIUM","STRONG"))))) | AX3: =IF(AV3<0.01,1,IF(AV3<0.02,2,IF(AV3<0.03,3,IF(AV3<0.04,4,IF(AV3<0.05,5,IF(AV3<0.06,6,IF(AV3<0.07,7,IF(AV3<0.08,8,IF(AV3<0.10,9,10))))))))) | AY3: =IF(AU3=H3,(O3)*(IF(AE3>0,AE3/100,100/ABS(AE3)))-(1-(O3)),(N3)*(IF(AD3>0,AD3/100,100/ABS(AD3)))-(1-(N3))) | AZ3: =IF(BS3>=BT3,"OVER","UNDER") | BA3: =MAX(0,BS3,BT3) | BB3: =IF(BA3<=0,"PASS",IF(BA3<0.02,"PASS",IF(BA3<0.04,"LEAN",IF(BA3<0.07,"SMALL",IF(BA3<0.10,"MEDIUM","STRONG"))))) | BC3: =IF(BA3<0.01,1,IF(BA3<0.02,2,IF(BA3<0.03,3,IF(BA3<0.04,4,IF(BA3<0.05,5,IF(BA3<0.06,6,IF(BA3<0.07,7,IF(BA3<0.08,8,IF(BA3<0.10,9,10))))))))) | BD3: =IF(AZ3="OVER",(BO3)*(IF(AG3>0,AG3/100,100/ABS(AG3)))-(1-(BO3)),(BP3)*(IF(AH3>0,AH3/100,100/ABS(AH3)))-(1-(BP3))) | BE3: =R3 | BF3: =IF(OR(ISBLANK(T3),ISBLANK(V3)),13,(V3-T3)/(2.56310313109)) | BG3: =IF(OR(ISNA(BF3),BF3<=0,ISBLANK(AB3)),NA(),1-NORMSDIST(((-AB3)-(BE3))/(BF3))) | BH3: =IF(OR(ISNA(BF3),BF3<=0,ISBLANK(Z3)),NA(),NORMSDIST(((Z3)-(BE3))/(BF3))) | BI3: =IF(OR(ISBLANK(AC3),AC3=0),NA(),IF(AC3>0,100/(AC3+100),-(AC3)/(-(AC3)+100))) | BJ3: =IF(OR(ISBLANK(AA3),AA3=0),NA(),IF(AA3>0,100/(AA3+100),-(AA3)/(-(AA3)+100))) | BK3: =BG3-BI3 | BL3: =BH3-BJ3 | BM3: =S3 | BN3: =IF(OR(ISBLANK(W3),ISBLANK(Y3)),16,(Y3-W3)/(2.56310313109)) | BO3: =IF(OR(ISNA(BN3),BN3<=0,ISBLANK(AF3)),NA(),1-NORMSDIST(((AF3)-(BM3))/(BN3))) | BP3: =IF(ISNA(BO3),NA(),1-(BO3)) | BQ3: =IF(OR(ISBLANK(AG3),AG3=0),NA(),IF(AG3>0,100/(AG3+100),-(AG3)/(-(AG3)+100))) | BR3: =IF(OR(ISBLANK(AH3),AH3=0),NA(),IF(AH3>0,100/(AH3+100),-(AH3)/(-(AH3)+100))) | BS3: =BO3-BQ3 | BT3: =BP3-BR3
A4: 2026 | B4: 1 | C4: 2026-09-13 | D4: 13:00 | E4: 46278.542 | F4: 2026_01_ATL_PIT | G4: ATL | H4: PIT | I4: 3.5 | J4: -3.5 | K4: 154 | L4: -185 | M4: 42.5 | N4: 0.4058 | O4: 0.5942 | P4: 20.8 | Q4: 23.2 | R4: 2.4 | S4: 43.9 | T4: -13.8 | U4: 2.3 | V4: 19.7 | W4: 27.1 | X4: 41.2 | Y4: 60.9 | Z4: 3.5 | AA4: -110 | AB4: =-Z4 | AC4: -110 | AD4: 154 | AE4: -185 | AF4: 42.5 | AG4: -110 | AH4: -110 | AI4: =IF(OR(ISBLANK(AB4),ISBLANK(R4)),NA(),R4+AB4) | AJ4: =IF(OR(ISBLANK(AD4),AD4=0),NA(),IF(AD4>0,100/(AD4+100),-(AD4)/(-(AD4)+100))) | AK4: =IF(OR(ISBLANK(AE4),AE4=0),NA(),IF(AE4>0,100/(AE4+100),-(AE4)/(-(AE4)+100))) | AL4: =IF(OR(ISNA(AK4),ISNA(AJ4)),NA(),AJ4/(AK4+AJ4)) | AM4: =IF(OR(ISNA(AK4),ISNA(AJ4)),NA(),AK4/(AK4+AJ4)) | AN4: =N4-AL4 | AO4: =O4-AM4 | AP4: =IF(BK4>=BL4,H4,G4) | AQ4: =MAX(0,BK4,BL4) | AR4: =IF(AQ4<=0,"PASS",IF(AQ4<0.02,"PASS",IF(AQ4<0.04,"LEAN",IF(AQ4<0.07,"SMALL",IF(AQ4<0.10,"MEDIUM","STRONG"))))) | AS4: =IF(AQ4<0.01,1,IF(AQ4<0.02,2,IF(AQ4<0.03,3,IF(AQ4<0.04,4,IF(AQ4<0.05,5,IF(AQ4<0.06,6,IF(AQ4<0.07,7,IF(AQ4<0.08,8,IF(AQ4<0.10,9,10))))))))) | AT4: =IF(AP4=H4,(BG4)*(IF(AC4>0,AC4/100,100/ABS(AC4)))-(1-(BG4)),(BH4)*(IF(AA4>0,AA4/100,100/ABS(AA4)))-(1-(BH4))) | AU4: =IF((O4-AK4)>=(N4-AJ4),H4,G4) | AV4: =MAX(0,(O4-AK4),(N4-AJ4)) | AW4: =IF(AV4<=0,"PASS",IF(AV4<0.02,"PASS",IF(AV4<0.04,"LEAN",IF(AV4<0.07,"SMALL",IF(AV4<0.10,"MEDIUM","STRONG"))))) | AX4: =IF(AV4<0.01,1,IF(AV4<0.02,2,IF(AV4<0.03,3,IF(AV4<0.04,4,IF(AV4<0.05,5,IF(AV4<0.06,6,IF(AV4<0.07,7,IF(AV4<0.08,8,IF(AV4<0.10,9,10))))))))) | AY4: =IF(AU4=H4,(O4)*(IF(AE4>0,AE4/100,100/ABS(AE4)))-(1-(O4)),(N4)*(IF(AD4>0,AD4/100,100/ABS(AD4)))-(1-(N4))) | AZ4: =IF(BS4>=BT4,"OVER","UNDER") | BA4: =MAX(0,BS4,BT4) | BB4: =IF(BA4<=0,"PASS",IF(BA4<0.02,"PASS",IF(BA4<0.04,"LEAN",IF(BA4<0.07,"SMALL",IF(BA4<0.10,"MEDIUM","STRONG"))))) | BC4: =IF(BA4<0.01,1,IF(BA4<0.02,2,IF(BA4<0.03,3,IF(BA4<0.04,4,IF(BA4<0.05,5,IF(BA4<0.06,6,IF(BA4<0.07,7,IF(BA4<0.08,8,IF(BA4<0.10,9,10))))))))) | BD4: =IF(AZ4="OVER",(BO4)*(IF(AG4>0,AG4/100,100/ABS(AG4)))-(1-(BO4)),(BP4)*(IF(AH4>0,AH4/100,100/ABS(AH4)))-(1-(BP4))) | BE4: =R4 | BF4: =IF(OR(ISBLANK(T4),ISBLANK(V4)),13,(V4-T4)/(2.56310313109)) | BG4: =IF(OR(ISNA(BF4),BF4<=0,ISBLANK(AB4)),NA(),1-NORMSDIST(((-AB4)-(BE4))/(BF4))) | BH4: =IF(OR(ISNA(BF4),BF4<=0,ISBLANK(Z4)),NA(),NORMSDIST(((Z4)-(BE4))/(BF4))) | BI4: =IF(OR(ISBLANK(AC4),AC4=0),NA(),IF(AC4>0,100/(AC4+100),-(AC4)/(-(AC4)+100))) | BJ4: =IF(OR(ISBLANK(AA4),AA4=0),NA(),IF(AA4>0,100/(AA4+100),-(AA4)/(-(AA4)+100))) | BK4: =BG4-BI4 | BL4: =BH4-BJ4 | BM4: =S4 | BN4: =IF(OR(ISBLANK(W4),ISBLANK(Y4)),16,(Y4-W4)/(2.56310313109)) | BO4: =IF(OR(ISNA(BN4),BN4<=0,ISBLANK(AF4)),NA(),1-NORMSDIST(((AF4)-(BM4))/(BN4))) | BP4: =IF(ISNA(BO4),NA(),1-(BO4)) | BQ4: =IF(OR(ISBLANK(AG4),AG4=0),NA(),IF(AG4>0,100/(AG4+100),-(AG4)/(-(AG4)+100))) | BR4: =IF(OR(ISBLANK(AH4),AH4=0),NA(),IF(AH4>0,100/(AH4+100),-(AH4)/(-(AH4)+100))) | BS4: =BO4-BQ4 | BT4: =BP4-BR4
A5: 2026 | B5: 1 | C5: 2026-09-13 | D5: 13:00 | E5: 46278.542 | F5: 2026_01_BAL_IND | G5: BAL | H5: IND | I5: -3.5 | J5: 3.5 | K5: -175 | L5: 145 | M5: 47.5 | N5: 0.6967 | O5: 0.3033 | P5: 24 | Q5: 20.2 | R5: -3.8 | S5: 44.1 | T5: -19.7 | U5: -3.4 | V5: 15.5 | W5: 29.4 | X5: 44.1 | Y5: 63.4 | Z5: -3.5 | AA5: -110 | AB5: =-Z5 | AC5: -110 | AD5: -175 | AE5: 145 | AF5: 47.5 | AG5: -110 | AH5: -110 | AI5: =IF(OR(ISBLANK(AB5),ISBLANK(R5)),NA(),R5+AB5) | AJ5: =IF(OR(ISBLANK(AD5),AD5=0),NA(),IF(AD5>0,100/(AD5+100),-(AD5)/(-(AD5)+100))) | AK5: =IF(OR(ISBLANK(AE5),AE5=0),NA(),IF(AE5>0,100/(AE5+100),-(AE5)/(-(AE5)+100))) | AL5: =IF(OR(ISNA(AK5),ISNA(AJ5)),NA(),AJ5/(AK5+AJ5)) | AM5: =IF(OR(ISNA(AK5),ISNA(AJ5)),NA(),AK5/(AK5+AJ5)) | AN5: =N5-AL5 | AO5: =O5-AM5 | AP5: =IF(BK5>=BL5,H5,G5) | AQ5: =MAX(0,BK5,BL5) | AR5: =IF(AQ5<=0,"PASS",IF(AQ5<0.02,"PASS",IF(AQ5<0.04,"LEAN",IF(AQ5<0.07,"SMALL",IF(AQ5<0.10,"MEDIUM","STRONG"))))) | AS5: =IF(AQ5<0.01,1,IF(AQ5<0.02,2,IF(AQ5<0.03,3,IF(AQ5<0.04,4,IF(AQ5<0.05,5,IF(AQ5<0.06,6,IF(AQ5<0.07,7,IF(AQ5<0.08,8,IF(AQ5<0.10,9,10))))))))) | AT5: =IF(AP5=H5,(BG5)*(IF(AC5>0,AC5/100,100/ABS(AC5)))-(1-(BG5)),(BH5)*(IF(AA5>0,AA5/100,100/ABS(AA5)))-(1-(BH5))) | AU5: =IF((O5-AK5)>=(N5-AJ5),H5,G5) | AV5: =MAX(0,(O5-AK5),(N5-AJ5)) | AW5: =IF(AV5<=0,"PASS",IF(AV5<0.02,"PASS",IF(AV5<0.04,"LEAN",IF(AV5<0.07,"SMALL",IF(AV5<0.10,"MEDIUM","STRONG"))))) | AX5: =IF(AV5<0.01,1,IF(AV5<0.02,2,IF(AV5<0.03,3,IF(AV5<0.04,4,IF(AV5<0.05,5,IF(AV5<0.06,6,IF(AV5<0.07,7,IF(AV5<0.08,8,IF(AV5<0.10,9,10))))))))) | AY5: =IF(AU5=H5,(O5)*(IF(AE5>0,AE5/100,100/ABS(AE5)))-(1-(O5)),(N5)*(IF(AD5>0,AD5/100,100/ABS(AD5)))-(1-(N5))) | AZ5: =IF(BS5>=BT5,"OVER","UNDER") | BA5: =MAX(0,BS5,BT5) | BB5: =IF(BA5<=0,"PASS",IF(BA5<0.02,"PASS",IF(BA5<0.04,"LEAN",IF(BA5<0.07,"SMALL",IF(BA5<0.10,"MEDIUM","STRONG"))))) | BC5: =IF(BA5<0.01,1,IF(BA5<0.02,2,IF(BA5<0.03,3,IF(BA5<0.04,4,IF(BA5<0.05,5,IF(BA5<0.06,6,IF(BA5<0.07,7,IF(BA5<0.08,8,IF(BA5<0.10,9,10))))))))) | BD5: =IF(AZ5="OVER",(BO5)*(IF(AG5>0,AG5/100,100/ABS(AG5)))-(1-(BO5)),(BP5)*(IF(AH5>0,AH5/100,100/ABS(AH5)))-(1-(BP5))) | BE5: =R5 | BF5: =IF(OR(ISBLANK(T5),ISBLANK(V5)),13,(V5-T5)/(2.56310313109)) | BG5: =IF(OR(ISNA(BF5),BF5<=0,ISBLANK(AB5)),NA(),1-NORMSDIST(((-AB5)-(BE5))/(BF5))) | BH5: =IF(OR(ISNA(BF5),BF5<=0,ISBLANK(Z5)),NA(),NORMSDIST(((Z5)-(BE5))/(BF5))) | BI5: =IF(OR(ISBLANK(AC5),AC5=0),NA(),IF(AC5>0,100/(AC5+100),-(AC5)/(-(AC5)+100))) | BJ5: =IF(OR(ISBLANK(AA5),AA5=0),NA(),IF(AA5>0,100/(AA5+100),-(AA5)/(-(AA5)+100))) | BK5: =BG5-BI5 | BL5: =BH5-BJ5 | BM5: =S5 | BN5: =IF(OR(ISBLANK(W5),ISBLANK(Y5)),16,(Y5-W5)/(2.56310313109)) | BO5: =IF(OR(ISNA(BN5),BN5<=0,ISBLANK(AF5)),NA(),1-NORMSDIST(((AF5)-(BM5))/(BN5))) | BP5: =IF(ISNA(BO5),NA(),1-(BO5)) | BQ5: =IF(OR(ISBLANK(AG5),AG5=0),NA(),IF(AG5>0,100/(AG5+100),-(AG5)/(-(AG5)+100))) | BR5: =IF(OR(ISBLANK(AH5),AH5=0),NA(),IF(AH5>0,100/(AH5+100),-(AH5)/(-(AH5)+100))) | BS5: =BO5-BQ5 | BT5: =BP5-BR5
A6: 2026 | B6: 1 | C6: 2026-09-13 | D6: 13:00 | E6: 46278.542 | F6: 2026_01_BUF_HOU | G6: BUF | H6: HOU | I6: -1.5 | J6: 1.5 | K6: -118 | L6: -102 | M6: 44.5 | N6: 0.6678 | O6: 0.3322 | P6: 23.5 | Q6: 20.4 | R6: -3.1 | S6: 43.9 | T6: -19.1 | U6: -1 | V6: 17.1 | W6: 28.2 | X6: 42.3 | Y6: 61.9 | Z6: -1.5 | AA6: -110 | AB6: =-Z6 | AC6: -110 | AD6: -118 | AE6: -102 | AF6: 44.5 | AG6: -110 | AH6: -110 | AI6: =IF(OR(ISBLANK(AB6),ISBLANK(R6)),NA(),R6+AB6) | AJ6: =IF(OR(ISBLANK(AD6),AD6=0),NA(),IF(AD6>0,100/(AD6+100),-(AD6)/(-(AD6)+100))) | AK6: =IF(OR(ISBLANK(AE6),AE6=0),NA(),IF(AE6>0,100/(AE6+100),-(AE6)/(-(AE6)+100))) | AL6: =IF(OR(ISNA(AK6),ISNA(AJ6)),NA(),AJ6/(AK6+AJ6)) | AM6: =IF(OR(ISNA(AK6),ISNA(AJ6)),NA(),AK6/(AK6+AJ6)) | AN6: =N6-AL6 | AO6: =O6-AM6 | AP6: =IF(BK6>=BL6,H6,G6) | AQ6: =MAX(0,BK6,BL6) | AR6: =IF(AQ6<=0,"PASS",IF(AQ6<0.02,"PASS",IF(AQ6<0.04,"LEAN",IF(AQ6<0.07,"SMALL",IF(AQ6<0.10,"MEDIUM","STRONG"))))) | AS6: =IF(AQ6<0.01,1,IF(AQ6<0.02,2,IF(AQ6<0.03,3,IF(AQ6<0.04,4,IF(AQ6<0.05,5,IF(AQ6<0.06,6,IF(AQ6<0.07,7,IF(AQ6<0.08,8,IF(AQ6<0.10,9,10))))))))) | AT6: =IF(AP6=H6,(BG6)*(IF(AC6>0,AC6/100,100/ABS(AC6)))-(1-(BG6)),(BH6)*(IF(AA6>0,AA6/100,100/ABS(AA6)))-(1-(BH6))) | AU6: =IF((O6-AK6)>=(N6-AJ6),H6,G6) | AV6: =MAX(0,(O6-AK6),(N6-AJ6)) | AW6: =IF(AV6<=0,"PASS",IF(AV6<0.02,"PASS",IF(AV6<0.04,"LEAN",IF(AV6<0.07,"SMALL",IF(AV6<0.10,"MEDIUM","STRONG"))))) | AX6: =IF(AV6<0.01,1,IF(AV6<0.02,2,IF(AV6<0.03,3,IF(AV6<0.04,4,IF(AV6<0.05,5,IF(AV6<0.06,6,IF(AV6<0.07,7,IF(AV6<0.08,8,IF(AV6<0.10,9,10))))))))) | AY6: =IF(AU6=H6,(O6)*(IF(AE6>0,AE6/100,100/ABS(AE6)))-(1-(O6)),(N6)*(IF(AD6>0,AD6/100,100/ABS(AD6)))-(1-(N6))) | AZ6: =IF(BS6>=BT6,"OVER","UNDER") | BA6: =MAX(0,BS6,BT6) | BB6: =IF(BA6<=0,"PASS",IF(BA6<0.02,"PASS",IF(BA6<0.04,"LEAN",IF(BA6<0.07,"SMALL",IF(BA6<0.10,"MEDIUM","STRONG"))))) | BC6: =IF(BA6<0.01,1,IF(BA6<0.02,2,IF(BA6<0.03,3,IF(BA6<0.04,4,IF(BA6<0.05,5,IF(BA6<0.06,6,IF(BA6<0.07,7,IF(BA6<0.08,8,IF(BA6<0.10,9,10))))))))) | BD6: =IF(AZ6="OVER",(BO6)*(IF(AG6>0,AG6/100,100/ABS(AG6)))-(1-(BO6)),(BP6)*(IF(AH6>0,AH6/100,100/ABS(AH6)))-(1-(BP6))) | BE6: =R6 | BF6: =IF(OR(ISBLANK(T6),ISBLANK(V6)),13,(V6-T6)/(2.56310313109)) | BG6: =IF(OR(ISNA(BF6),BF6<=0,ISBLANK(AB6)),NA(),1-NORMSDIST(((-AB6)-(BE6))/(BF6))) | BH6: =IF(OR(ISNA(BF6),BF6<=0,ISBLANK(Z6)),NA(),NORMSDIST(((Z6)-(BE6))/(BF6))) | BI6: =IF(OR(ISBLANK(AC6),AC6=0),NA(),IF(AC6>0,100/(AC6+100),-(AC6)/(-(AC6)+100))) | BJ6: =IF(OR(ISBLANK(AA6),AA6=0),NA(),IF(AA6>0,100/(AA6+100),-(AA6)/(-(AA6)+100))) | BK6: =BG6-BI6 | BL6: =BH6-BJ6 | BM6: =S6 | BN6: =IF(OR(ISBLANK(W6),ISBLANK(Y6)),16,(Y6-W6)/(2.56310313109)) | BO6: =IF(OR(ISNA(BN6),BN6<=0,ISBLANK(AF6)),NA(),1-NORMSDIST(((AF6)-(BM6))/(BN6))) | BP6: =IF(ISNA(BO6),NA(),1-(BO6)) | BQ6: =IF(OR(ISBLANK(AG6),AG6=0),NA(),IF(AG6>0,100/(AG6+100),-(AG6)/(-(AG6)+100))) | BR6: =IF(OR(ISBLANK(AH6),AH6=0),NA(),IF(AH6>0,100/(AH6+100),-(AH6)/(-(AH6)+100))) | BS6: =BO6-BQ6 | BT6: =BP6-BR6
A7: 2026 | B7: 1 | C7: 2026-09-13 | D7: 13:00 | E7: 46278.542 | F7: 2026_01_CHI_CAR | G7: CHI | H7: CAR | I7: -3 | J7: 3 | K7: -162 | L7: 136 | M7: 46.5 | N7: 0.6873 | O7: 0.3127 | P7: 23.8 | Q7: 20.2 | R7: -3.6 | S7: 44.1 | T7: -18.6 | U7: -1.8 | V7: 12.9 | W7: 28.9 | X7: 42.9 | Y7: 61.8 | Z7: -3 | AA7: -110 | AB7: =-Z7 | AC7: -110 | AD7: -162 | AE7: 136 | AF7: 46.5 | AG7: -110 | AH7: -110 | AI7: =IF(OR(ISBLANK(AB7),ISBLANK(R7)),NA(),R7+AB7) | AJ7: =IF(OR(ISBLANK(AD7),AD7=0),NA(),IF(AD7>0,100/(AD7+100),-(AD7)/(-(AD7)+100))) | AK7: =IF(OR(ISBLANK(AE7),AE7=0),NA(),IF(AE7>0,100/(AE7+100),-(AE7)/(-(AE7)+100))) | AL7: =IF(OR(ISNA(AK7),ISNA(AJ7)),NA(),AJ7/(AK7+AJ7)) | AM7: =IF(OR(ISNA(AK7),ISNA(AJ7)),NA(),AK7/(AK7+AJ7)) | AN7: =N7-AL7 | AO7: =O7-AM7 | AP7: =IF(BK7>=BL7,H7,G7) | AQ7: =MAX(0,BK7,BL7) | AR7: =IF(AQ7<=0,"PASS",IF(AQ7<0.02,"PASS",IF(AQ7<0.04,"LEAN",IF(AQ7<0.07,"SMALL",IF(AQ7<0.10,"MEDIUM","STRONG"))))) | AS7: =IF(AQ7<0.01,1,IF(AQ7<0.02,2,IF(AQ7<0.03,3,IF(AQ7<0.04,4,IF(AQ7<0.05,5,IF(AQ7<0.06,6,IF(AQ7<0.07,7,IF(AQ7<0.08,8,IF(AQ7<0.10,9,10))))))))) | AT7: =IF(AP7=H7,(BG7)*(IF(AC7>0,AC7/100,100/ABS(AC7)))-(1-(BG7)),(BH7)*(IF(AA7>0,AA7/100,100/ABS(AA7)))-(1-(BH7))) | AU7: =IF((O7-AK7)>=(N7-AJ7),H7,G7) | AV7: =MAX(0,(O7-AK7),(N7-AJ7)) | AW7: =IF(AV7<=0,"PASS",IF(AV7<0.02,"PASS",IF(AV7<0.04,"LEAN",IF(AV7<0.07,"SMALL",IF(AV7<0.10,"MEDIUM","STRONG"))))) | AX7: =IF(AV7<0.01,1,IF(AV7<0.02,2,IF(AV7<0.03,3,IF(AV7<0.04,4,IF(AV7<0.05,5,IF(AV7<0.06,6,IF(AV7<0.07,7,IF(AV7<0.08,8,IF(AV7<0.10,9,10))))))))) | AY7: =IF(AU7=H7,(O7)*(IF(AE7>0,AE7/100,100/ABS(AE7)))-(1-(O7)),(N7)*(IF(AD7>0,AD7/100,100/ABS(AD7)))-(1-(N7))) | AZ7: =IF(BS7>=BT7,"OVER","UNDER") | BA7: =MAX(0,BS7,BT7) | BB7: =IF(BA7<=0,"PASS",IF(BA7<0.02,"PASS",IF(BA7<0.04,"LEAN",IF(BA7<0.07,"SMALL",IF(BA7<0.10,"MEDIUM","STRONG"))))) | BC7: =IF(BA7<0.01,1,IF(BA7<0.02,2,IF(BA7<0.03,3,IF(BA7<0.04,4,IF(BA7<0.05,5,IF(BA7<0.06,6,IF(BA7<0.07,7,IF(BA7<0.08,8,IF(BA7<0.10,9,10))))))))) | BD7: =IF(AZ7="OVER",(BO7)*(IF(AG7>0,AG7/100,100/ABS(AG7)))-(1-(BO7)),(BP7)*(IF(AH7>0,AH7/100,100/ABS(AH7)))-(1-(BP7))) | BE7: =R7 | BF7: =IF(OR(ISBLANK(T7),ISBLANK(V7)),13,(V7-T7)/(2.56310313109)) | BG7: =IF(OR(ISNA(BF7),BF7<=0,ISBLANK(AB7)),NA(),1-NORMSDIST(((-AB7)-(BE7))/(BF7))) | BH7: =IF(OR(ISNA(BF7),BF7<=0,ISBLANK(Z7)),NA(),NORMSDIST(((Z7)-(BE7))/(BF7))) | BI7: =IF(OR(ISBLANK(AC7),AC7=0),NA(),IF(AC7>0,100/(AC7+100),-(AC7)/(-(AC7)+100))) | BJ7: =IF(OR(ISBLANK(AA7),AA7=0),NA(),IF(AA7>0,100/(AA7+100),-(AA7)/(-(AA7)+100))) | BK7: =BG7-BI7 | BL7: =BH7-BJ7 | BM7: =S7 | BN7: =IF(OR(ISBLANK(W7),ISBLANK(Y7)),16,(Y7-W7)/(2.56310313109)) | BO7: =IF(OR(ISNA(BN7),BN7<=0,ISBLANK(AF7)),NA(),1-NORMSDIST(((AF7)-(BM7))/(BN7))) | BP7: =IF(ISNA(BO7),NA(),1-(BO7)) | BQ7: =IF(OR(ISBLANK(AG7),AG7=0),NA(),IF(AG7>0,100/(AG7+100),-(AG7)/(-(AG7)+100))) | BR7: =IF(OR(ISBLANK(AH7),AH7=0),NA(),IF(AH7>0,100/(AH7+100),-(AH7)/(-(AH7)+100))) | BS7: =BO7-BQ7 | BT7: =BP7-BR7
A8: 2026 | B8: 1 | C8: 2026-09-13 | D8: 13:00 | E8: 46278.542 | F8: 2026_01_CLE_JAX | G8: CLE | H8: JAX | I8: 8.5 | J8: -8.5 | K8: 360 | L8: -470 | M8: 40.5 | N8: 0.1827 | O8: 0.8173 | P8: 17.9 | Q8: 26.1 | R8: 8.1 | S8: 44 | T8: -6.2 | U8: 8.6 | V8: 24.9 | W8: 26 | X8: 40.9 | Y8: 57.8 | Z8: 8.5 | AA8: -110 | AB8: =-Z8 | AC8: -110 | AD8: 360 | AE8: -470 | AF8: 40.5 | AG8: -110 | AH8: -110 | AI8: =IF(OR(ISBLANK(AB8),ISBLANK(R8)),NA(),R8+AB8) | AJ8: =IF(OR(ISBLANK(AD8),AD8=0),NA(),IF(AD8>0,100/(AD8+100),-(AD8)/(-(AD8)+100))) | AK8: =IF(OR(ISBLANK(AE8),AE8=0),NA(),IF(AE8>0,100/(AE8+100),-(AE8)/(-(AE8)+100))) | AL8: =IF(OR(ISNA(AK8),ISNA(AJ8)),NA(),AJ8/(AK8+AJ8)) | AM8: =IF(OR(ISNA(AK8),ISNA(AJ8)),NA(),AK8/(AK8+AJ8)) | AN8: =N8-AL8 | AO8: =O8-AM8 | AP8: =IF(BK8>=BL8,H8,G8) | AQ8: =MAX(0,BK8,BL8) | AR8: =IF(AQ8<=0,"PASS",IF(AQ8<0.02,"PASS",IF(AQ8<0.04,"LEAN",IF(AQ8<0.07,"SMALL",IF(AQ8<0.10,"MEDIUM","STRONG"))))) | AS8: =IF(AQ8<0.01,1,IF(AQ8<0.02,2,IF(AQ8<0.03,3,IF(AQ8<0.04,4,IF(AQ8<0.05,5,IF(AQ8<0.06,6,IF(AQ8<0.07,7,IF(AQ8<0.08,8,IF(AQ8<0.10,9,10))))))))) | AT8: =IF(AP8=H8,(BG8)*(IF(AC8>0,AC8/100,100/ABS(AC8)))-(1-(BG8)),(BH8)*(IF(AA8>0,AA8/100,100/ABS(AA8)))-(1-(BH8))) | AU8: =IF((O8-AK8)>=(N8-AJ8),H8,G8) | AV8: =MAX(0,(O8-AK8),(N8-AJ8)) | AW8: =IF(AV8<=0,"PASS",IF(AV8<0.02,"PASS",IF(AV8<0.04,"LEAN",IF(AV8<0.07,"SMALL",IF(AV8<0.10,"MEDIUM","STRONG"))))) | AX8: =IF(AV8<0.01,1,IF(AV8<0.02,2,IF(AV8<0.03,3,IF(AV8<0.04,4,IF(AV8<0.05,5,IF(AV8<0.06,6,IF(AV8<0.07,7,IF(AV8<0.08,8,IF(AV8<0.10,9,10))))))))) | AY8: =IF(AU8=H8,(O8)*(IF(AE8>0,AE8/100,100/ABS(AE8)))-(1-(O8)),(N8)*(IF(AD8>0,AD8/100,100/ABS(AD8)))-(1-(N8))) | AZ8: =IF(BS8>=BT8,"OVER","UNDER") | BA8: =MAX(0,BS8,BT8) | BB8: =IF(BA8<=0,"PASS",IF(BA8<0.02,"PASS",IF(BA8<0.04,"LEAN",IF(BA8<0.07,"SMALL",IF(BA8<0.10,"MEDIUM","STRONG"))))) | BC8: =IF(BA8<0.01,1,IF(BA8<0.02,2,IF(BA8<0.03,3,IF(BA8<0.04,4,IF(BA8<0.05,5,IF(BA8<0.06,6,IF(BA8<0.07,7,IF(BA8<0.08,8,IF(BA8<0.10,9,10))))))))) | BD8: =IF(AZ8="OVER",(BO8)*(IF(AG8>0,AG8/100,100/ABS(AG8)))-(1-(BO8)),(BP8)*(IF(AH8>0,AH8/100,100/ABS(AH8)))-(1-(BP8))) | BE8: =R8 | BF8: =IF(OR(ISBLANK(T8),ISBLANK(V8)),13,(V8-T8)/(2.56310313109)) | BG8: =IF(OR(ISNA(BF8),BF8<=0,ISBLANK(AB8)),NA(),1-NORMSDIST(((-AB8)-(BE8))/(BF8))) | BH8: =IF(OR(ISNA(BF8),BF8<=0,ISBLANK(Z8)),NA(),NORMSDIST(((Z8)-(BE8))/(BF8))) | BI8: =IF(OR(ISBLANK(AC8),AC8=0),NA(),IF(AC8>0,100/(AC8+100),-(AC8)/(-(AC8)+100))) | BJ8: =IF(OR(ISBLANK(AA8),AA8=0),NA(),IF(AA8>0,100/(AA8+100),-(AA8)/(-(AA8)+100))) | BK8: =BG8-BI8 | BL8: =BH8-BJ8 | BM8: =S8 | BN8: =IF(OR(ISBLANK(W8),ISBLANK(Y8)),16,(Y8-W8)/(2.56310313109)) | BO8: =IF(OR(ISNA(BN8),BN8<=0,ISBLANK(AF8)),NA(),1-NORMSDIST(((AF8)-(BM8))/(BN8))) | BP8: =IF(ISNA(BO8),NA(),1-(BO8)) | BQ8: =IF(OR(ISBLANK(AG8),AG8=0),NA(),IF(AG8>0,100/(AG8+100),-(AG8)/(-(AG8)+100))) | BR8: =IF(OR(ISBLANK(AH8),AH8=0),NA(),IF(AH8>0,100/(AH8+100),-(AH8)/(-(AH8)+100))) | BS8: =BO8-BQ8 | BT8: =BP8-BR8
A9: 2026 | B9: 1 | C9: 2026-09-13 | D9: 13:00 | E9: 46278.542 | F9: 2026_01_NO_DET | G9: NO | H9: DET | I9: 7 | J9: -7 | K9: 250 | L9: -310 | M9: 49.5 | N9: 0.2146 | O9: 0.7854 | P9: 18.5 | Q9: 25.6 | R9: 7.1 | S9: 44.1 | T9: -10.4 | U9: 6.8 | V9: 23.1 | W9: 29.6 | X9: 44.9 | Y9: 64.7 | Z9: 7 | AA9: -110 | AB9: =-Z9 | AC9: -110 | AD9: 250 | AE9: -310 | AF9: 49.5 | AG9: -110 | AH9: -110 | AI9: =IF(OR(ISBLANK(AB9),ISBLANK(R9)),NA(),R9+AB9) | AJ9: =IF(OR(ISBLANK(AD9),AD9=0),NA(),IF(AD9>0,100/(AD9+100),-(AD9)/(-(AD9)+100))) | AK9: =IF(OR(ISBLANK(AE9),AE9=0),NA(),IF(AE9>0,100/(AE9+100),-(AE9)/(-(AE9)+100))) | AL9: =IF(OR(ISNA(AK9),ISNA(AJ9)),NA(),AJ9/(AK9+AJ9)) | AM9: =IF(OR(ISNA(AK9),ISNA(AJ9)),NA(),AK9/(AK9+AJ9)) | AN9: =N9-AL9 | AO9: =O9-AM9 | AP9: =IF(BK9>=BL9,H9,G9) | AQ9: =MAX(0,BK9,BL9) | AR9: =IF(AQ9<=0,"PASS",IF(AQ9<0.02,"PASS",IF(AQ9<0.04,"LEAN",IF(AQ9<0.07,"SMALL",IF(AQ9<0.10,"MEDIUM","STRONG"))))) | AS9: =IF(AQ9<0.01,1,IF(AQ9<0.02,2,IF(AQ9<0.03,3,IF(AQ9<0.04,4,IF(AQ9<0.05,5,IF(AQ9<0.06,6,IF(AQ9<0.07,7,IF(AQ9<0.08,8,IF(AQ9<0.10,9,10))))))))) | AT9: =IF(AP9=H9,(BG9)*(IF(AC9>0,AC9/100,100/ABS(AC9)))-(1-(BG9)),(BH9)*(IF(AA9>0,AA9/100,100/ABS(AA9)))-(1-(BH9))) | AU9: =IF((O9-AK9)>=(N9-AJ9),H9,G9) | AV9: =MAX(0,(O9-AK9),(N9-AJ9)) | AW9: =IF(AV9<=0,"PASS",IF(AV9<0.02,"PASS",IF(AV9<0.04,"LEAN",IF(AV9<0.07,"SMALL",IF(AV9<0.10,"MEDIUM","STRONG"))))) | AX9: =IF(AV9<0.01,1,IF(AV9<0.02,2,IF(AV9<0.03,3,IF(AV9<0.04,4,IF(AV9<0.05,5,IF(AV9<0.06,6,IF(AV9<0.07,7,IF(AV9<0.08,8,IF(AV9<0.10,9,10))))))))) | AY9: =IF(AU9=H9,(O9)*(IF(AE9>0,AE9/100,100/ABS(AE9)))-(1-(O9)),(N9)*(IF(AD9>0,AD9/100,100/ABS(AD9)))-(1-(N9))) | AZ9: =IF(BS9>=BT9,"OVER","UNDER") | BA9: =MAX(0,BS9,BT9) | BB9: =IF(BA9<=0,"PASS",IF(BA9<0.02,"PASS",IF(BA9<0.04,"LEAN",IF(BA9<0.07,"SMALL",IF(BA9<0.10,"MEDIUM","STRONG"))))) | BC9: =IF(BA9<0.01,1,IF(BA9<0.02,2,IF(BA9<0.03,3,IF(BA9<0.04,4,IF(BA9<0.05,5,IF(BA9<0.06,6,IF(BA9<0.07,7,IF(BA9<0.08,8,IF(BA9<0.10,9,10))))))))) | BD9: =IF(AZ9="OVER",(BO9)*(IF(AG9>0,AG9/100,100/ABS(AG9)))-(1-(BO9)),(BP9)*(IF(AH9>0,AH9/100,100/ABS(AH9)))-(1-(BP9))) | BE9: =R9 | BF9: =IF(OR(ISBLANK(T9),ISBLANK(V9)),13,(V9-T9)/(2.56310313109)) | BG9: =IF(OR(ISNA(BF9),BF9<=0,ISBLANK(AB9)),NA(),1-NORMSDIST(((-AB9)-(BE9))/(BF9))) | BH9: =IF(OR(ISNA(BF9),BF9<=0,ISBLANK(Z9)),NA(),NORMSDIST(((Z9)-(BE9))/(BF9))) | BI9: =IF(OR(ISBLANK(AC9),AC9=0),NA(),IF(AC9>0,100/(AC9+100),-(AC9)/(-(AC9)+100))) | BJ9: =IF(OR(ISBLANK(AA9),AA9=0),NA(),IF(AA9>0,100/(AA9+100),-(AA9)/(-(AA9)+100))) | BK9: =BG9-BI9 | BL9: =BH9-BJ9 | BM9: =S9 | BN9: =IF(OR(ISBLANK(W9),ISBLANK(Y9)),16,(Y9-W9)/(2.56310313109)) | BO9: =IF(OR(ISNA(BN9),BN9<=0,ISBLANK(AF9)),NA(),1-NORMSDIST(((AF9)-(BM9))/(BN9))) | BP9: =IF(ISNA(BO9),NA(),1-(BO9)) | BQ9: =IF(OR(ISBLANK(AG9),AG9=0),NA(),IF(AG9>0,100/(AG9+100),-(AG9)/(-(AG9)+100))) | BR9: =IF(OR(ISBLANK(AH9),AH9=0),NA(),IF(AH9>0,100/(AH9+100),-(AH9)/(-(AH9)+100))) | BS9: =BO9-BQ9 | BT9: =BP9-BR9
A10: 2026 | B10: 1 | C10: 2026-09-13 | D10: 13:00 | E10: 46278.542 | F10: 2026_01_NYJ_TEN | G10: NYJ | H10: TEN | I10: 1.5 | J10: -1.5 | K10: 102 | L10: -122 | M10: 38.5 | N10: 0.6188 | O10: 0.3812 | P10: 23 | Q10: 20.9 | R10: -2 | S10: 43.9 | T10: -14.7 | U10: 0.1 | V10: 16.7 | W10: 25.4 | X10: 39.8 | Y10: 57.6 | Z10: 1.5 | AA10: -110 | AB10: =-Z10 | AC10: -110 | AD10: 102 | AE10: -122 | AF10: 38.5 | AG10: -110 | AH10: -110 | AI10: =IF(OR(ISBLANK(AB10),ISBLANK(R10)),NA(),R10+AB10) | AJ10: =IF(OR(ISBLANK(AD10),AD10=0),NA(),IF(AD10>0,100/(AD10+100),-(AD10)/(-(AD10)+100))) | AK10: =IF(OR(ISBLANK(AE10),AE10=0),NA(),IF(AE10>0,100/(AE10+100),-(AE10)/(-(AE10)+100))) | AL10: =IF(OR(ISNA(AK10),ISNA(AJ10)),NA(),AJ10/(AK10+AJ10)) | AM10: =IF(OR(ISNA(AK10),ISNA(AJ10)),NA(),AK10/(AK10+AJ10)) | AN10: =N10-AL10 | AO10: =O10-AM10 | AP10: =IF(BK10>=BL10,H10,G10) | AQ10: =MAX(0,BK10,BL10) | AR10: =IF(AQ10<=0,"PASS",IF(AQ10<0.02,"PASS",IF(AQ10<0.04,"LEAN",IF(AQ10<0.07,"SMALL",IF(AQ10<0.10,"MEDIUM","STRONG"))))) | AS10: =IF(AQ10<0.01,1,IF(AQ10<0.02,2,IF(AQ10<0.03,3,IF(AQ10<0.04,4,IF(AQ10<0.05,5,IF(AQ10<0.06,6,IF(AQ10<0.07,7,IF(AQ10<0.08,8,IF(AQ10<0.10,9,10))))))))) | AT10: =IF(AP10=H10,(BG10)*(IF(AC10>0,AC10/100,100/ABS(AC10)))-(1-(BG10)),(BH10)*(IF(AA10>0,AA10/100,100/ABS(AA10)))-(1-(BH10))) | AU10: =IF((O10-AK10)>=(N10-AJ10),H10,G10) | AV10: =MAX(0,(O10-AK10),(N10-AJ10)) | AW10: =IF(AV10<=0,"PASS",IF(AV10<0.02,"PASS",IF(AV10<0.04,"LEAN",IF(AV10<0.07,"SMALL",IF(AV10<0.10,"MEDIUM","STRONG"))))) | AX10: =IF(AV10<0.01,1,IF(AV10<0.02,2,IF(AV10<0.03,3,IF(AV10<0.04,4,IF(AV10<0.05,5,IF(AV10<0.06,6,IF(AV10<0.07,7,IF(AV10<0.08,8,IF(AV10<0.10,9,10))))))))) | AY10: =IF(AU10=H10,(O10)*(IF(AE10>0,AE10/100,100/ABS(AE10)))-(1-(O10)),(N10)*(IF(AD10>0,AD10/100,100/ABS(AD10)))-(1-(N10))) | AZ10: =IF(BS10>=BT10,"OVER","UNDER") | BA10: =MAX(0,BS10,BT10) | BB10: =IF(BA10<=0,"PASS",IF(BA10<0.02,"PASS",IF(BA10<0.04,"LEAN",IF(BA10<0.07,"SMALL",IF(BA10<0.10,"MEDIUM","STRONG"))))) | BC10: =IF(BA10<0.01,1,IF(BA10<0.02,2,IF(BA10<0.03,3,IF(BA10<0.04,4,IF(BA10<0.05,5,IF(BA10<0.06,6,IF(BA10<0.07,7,IF(BA10<0.08,8,IF(BA10<0.10,9,10))))))))) | BD10: =IF(AZ10="OVER",(BO10)*(IF(AG10>0,AG10/100,100/ABS(AG10)))-(1-(BO10)),(BP10)*(IF(AH10>0,AH10/100,100/ABS(AH10)))-(1-(BP10))) | BE10: =R10 | BF10: =IF(OR(ISBLANK(T10),ISBLANK(V10)),13,(V10-T10)/(2.56310313109)) | BG10: =IF(OR(ISNA(BF10),BF10<=0,ISBLANK(AB10)),NA(),1-NORMSDIST(((-AB10)-(BE10))/(BF10))) | BH10: =IF(OR(ISNA(BF10),BF10<=0,ISBLANK(Z10)),NA(),NORMSDIST(((Z10)-(BE10))/(BF10))) | BI10: =IF(OR(ISBLANK(AC10),AC10=0),NA(),IF(AC10>0,100/(AC10+100),-(AC10)/(-(AC10)+100))) | BJ10: =IF(OR(ISBLANK(AA10),AA10=0),NA(),IF(AA10>0,100/(AA10+100),-(AA10)/(-(AA10)+100))) | BK10: =BG10-BI10 | BL10: =BH10-BJ10 | BM10: =S10 | BN10: =IF(OR(ISBLANK(W10),ISBLANK(Y10)),16,(Y10-W10)/(2.56310313109)) | BO10: =IF(OR(ISNA(BN10),BN10<=0,ISBLANK(AF10)),NA(),1-NORMSDIST(((AF10)-(BM10))/(BN10))) | BP10: =IF(ISNA(BO10),NA(),1-(BO10)) | BQ10: =IF(OR(ISBLANK(AG10),AG10=0),NA(),IF(AG10>0,100/(AG10+100),-(AG10)/(-(AG10)+100))) | BR10: =IF(OR(ISBLANK(AH10),AH10=0),NA(),IF(AH10>0,100/(AH10+100),-(AH10)/(-(AH10)+100))) | BS10: =BO10-BQ10 | BT10: =BP10-BR10
A11: 2026 | B11: 1 | C11: 2026-09-13 | D11: 13:00 | E11: 46278.542 | F11: 2026_01_TB_CIN | G11: TB | H11: CIN | I11: 3.5 | J11: -3.5 | K11: 164 | L11: -198 | M11: 50.5 | N11: 0.4228 | O11: 0.5772 | P11: 21 | Q11: 23.1 | R11: 2 | S11: 44.1 | T11: -13.3 | U11: 3.2 | V11: 18.8 | W11: 32.5 | X11: 46.2 | Y11: 64.4 | Z11: 3.5 | AA11: -110 | AB11: =-Z11 | AC11: -110 | AD11: 164 | AE11: -198 | AF11: 50.5 | AG11: -110 | AH11: -110 | AI11: =IF(OR(ISBLANK(AB11),ISBLANK(R11)),NA(),R11+AB11) | AJ11: =IF(OR(ISBLANK(AD11),AD11=0),NA(),IF(AD11>0,100/(AD11+100),-(AD11)/(-(AD11)+100))) | AK11: =IF(OR(ISBLANK(AE11),AE11=0),NA(),IF(AE11>0,100/(AE11+100),-(AE11)/(-(AE11)+100))) | AL11: =IF(OR(ISNA(AK11),ISNA(AJ11)),NA(),AJ11/(AK11+AJ11)) | AM11: =IF(OR(ISNA(AK11),ISNA(AJ11)),NA(),AK11/(AK11+AJ11)) | AN11: =N11-AL11 | AO11: =O11-AM11 | AP11: =IF(BK11>=BL11,H11,G11) | AQ11: =MAX(0,BK11,BL11) | AR11: =IF(AQ11<=0,"PASS",IF(AQ11<0.02,"PASS",IF(AQ11<0.04,"LEAN",IF(AQ11<0.07,"SMALL",IF(AQ11<0.10,"MEDIUM","STRONG"))))) | AS11: =IF(AQ11<0.01,1,IF(AQ11<0.02,2,IF(AQ11<0.03,3,IF(AQ11<0.04,4,IF(AQ11<0.05,5,IF(AQ11<0.06,6,IF(AQ11<0.07,7,IF(AQ11<0.08,8,IF(AQ11<0.10,9,10))))))))) | AT11: =IF(AP11=H11,(BG11)*(IF(AC11>0,AC11/100,100/ABS(AC11)))-(1-(BG11)),(BH11)*(IF(AA11>0,AA11/100,100/ABS(AA11)))-(1-(BH11))) | AU11: =IF((O11-AK11)>=(N11-AJ11),H11,G11) | AV11: =MAX(0,(O11-AK11),(N11-AJ11)) | AW11: =IF(AV11<=0,"PASS",IF(AV11<0.02,"PASS",IF(AV11<0.04,"LEAN",IF(AV11<0.07,"SMALL",IF(AV11<0.10,"MEDIUM","STRONG"))))) | AX11: =IF(AV11<0.01,1,IF(AV11<0.02,2,IF(AV11<0.03,3,IF(AV11<0.04,4,IF(AV11<0.05,5,IF(AV11<0.06,6,IF(AV11<0.07,7,IF(AV11<0.08,8,IF(AV11<0.10,9,10))))))))) | AY11: =IF(AU11=H11,(O11)*(IF(AE11>0,AE11/100,100/ABS(AE11)))-(1-(O11)),(N11)*(IF(AD11>0,AD11/100,100/ABS(AD11)))-(1-(N11))) | AZ11: =IF(BS11>=BT11,"OVER","UNDER") | BA11: =MAX(0,BS11,BT11) | BB11: =IF(BA11<=0,"PASS",IF(BA11<0.02,"PASS",IF(BA11<0.04,"LEAN",IF(BA11<0.07,"SMALL",IF(BA11<0.10,"MEDIUM","STRONG"))))) | BC11: =IF(BA11<0.01,1,IF(BA11<0.02,2,IF(BA11<0.03,3,IF(BA11<0.04,4,IF(BA11<0.05,5,IF(BA11<0.06,6,IF(BA11<0.07,7,IF(BA11<0.08,8,IF(BA11<0.10,9,10))))))))) | BD11: =IF(AZ11="OVER",(BO11)*(IF(AG11>0,AG11/100,100/ABS(AG11)))-(1-(BO11)),(BP11)*(IF(AH11>0,AH11/100,100/ABS(AH11)))-(1-(BP11))) | BE11: =R11 | BF11: =IF(OR(ISBLANK(T11),ISBLANK(V11)),13,(V11-T11)/(2.56310313109)) | BG11: =IF(OR(ISNA(BF11),BF11<=0,ISBLANK(AB11)),NA(),1-NORMSDIST(((-AB11)-(BE11))/(BF11))) | BH11: =IF(OR(ISNA(BF11),BF11<=0,ISBLANK(Z11)),NA(),NORMSDIST(((Z11)-(BE11))/(BF11))) | BI11: =IF(OR(ISBLANK(AC11),AC11=0),NA(),IF(AC11>0,100/(AC11+100),-(AC11)/(-(AC11)+100))) | BJ11: =IF(OR(ISBLANK(AA11),AA11=0),NA(),IF(AA11>0,100/(AA11+100),-(AA11)/(-(AA11)+100))) | BK11: =BG11-BI11 | BL11: =BH11-BJ11 | BM11: =S11 | BN11: =IF(OR(ISBLANK(W11),ISBLANK(Y11)),16,(Y11-W11)/(2.56310313109)) | BO11: =IF(OR(ISNA(BN11),BN11<=0,ISBLANK(AF11)),NA(),1-NORMSDIST(((AF11)-(BM11))/(BN11))) | BP11: =IF(ISNA(BO11),NA(),1-(BO11)) | BQ11: =IF(OR(ISBLANK(AG11),AG11=0),NA(),IF(AG11>0,100/(AG11+100),-(AG11)/(-(AG11)+100))) | BR11: =IF(OR(ISBLANK(AH11),AH11=0),NA(),IF(AH11>0,100/(AH11+100),-(AH11)/(-(AH11)+100))) | BS11: =BO11-BQ11 | BT11: =BP11-BR11
A12: 2026 | B12: 1 | C12: 2026-09-13 | D12: 16:25 | E12: 46278.684 | F12: 2026_01_ARI_LAC | G12: ARI | H12: LAC | I12: 9.5 | J12: -9.5 | K12: 380 | L12: -500 | M12: 47.5 | N12: 0.2013 | O12: 0.7987 | P12: 18.3 | Q12: 25.8 | R12: 7.5 | S12: 44.1 | T12: -6 | U12: 6.3 | V12: 22.5 | W12: 30.8 | X12: 44.3 | Y12: 64.8 | Z12: 9.5 | AA12: -110 | AB12: =-Z12 | AC12: -110 | AD12: 380 | AE12: -500 | AF12: 47.5 | AG12: -110 | AH12: -110 | AI12: =IF(OR(ISBLANK(AB12),ISBLANK(R12)),NA(),R12+AB12) | AJ12: =IF(OR(ISBLANK(AD12),AD12=0),NA(),IF(AD12>0,100/(AD12+100),-(AD12)/(-(AD12)+100))) | AK12: =IF(OR(ISBLANK(AE12),AE12=0),NA(),IF(AE12>0,100/(AE12+100),-(AE12)/(-(AE12)+100))) | AL12: =IF(OR(ISNA(AK12),ISNA(AJ12)),NA(),AJ12/(AK12+AJ12)) | AM12: =IF(OR(ISNA(AK12),ISNA(AJ12)),NA(),AK12/(AK12+AJ12)) | AN12: =N12-AL12 | AO12: =O12-AM12 | AP12: =IF(BK12>=BL12,H12,G12) | AQ12: =MAX(0,BK12,BL12) | AR12: =IF(AQ12<=0,"PASS",IF(AQ12<0.02,"PASS",IF(AQ12<0.04,"LEAN",IF(AQ12<0.07,"SMALL",IF(AQ12<0.10,"MEDIUM","STRONG"))))) | AS12: =IF(AQ12<0.01,1,IF(AQ12<0.02,2,IF(AQ12<0.03,3,IF(AQ12<0.04,4,IF(AQ12<0.05,5,IF(AQ12<0.06,6,IF(AQ12<0.07,7,IF(AQ12<0.08,8,IF(AQ12<0.10,9,10))))))))) | AT12: =IF(AP12=H12,(BG12)*(IF(AC12>0,AC12/100,100/ABS(AC12)))-(1-(BG12)),(BH12)*(IF(AA12>0,AA12/100,100/ABS(AA12)))-(1-(BH12))) | AU12: =IF((O12-AK12)>=(N12-AJ12),H12,G12) | AV12: =MAX(0,(O12-AK12),(N12-AJ12)) | AW12: =IF(AV12<=0,"PASS",IF(AV12<0.02,"PASS",IF(AV12<0.04,"LEAN",IF(AV12<0.07,"SMALL",IF(AV12<0.10,"MEDIUM","STRONG"))))) | AX12: =IF(AV12<0.01,1,IF(AV12<0.02,2,IF(AV12<0.03,3,IF(AV12<0.04,4,IF(AV12<0.05,5,IF(AV12<0.06,6,IF(AV12<0.07,7,IF(AV12<0.08,8,IF(AV12<0.10,9,10))))))))) | AY12: =IF(AU12=H12,(O12)*(IF(AE12>0,AE12/100,100/ABS(AE12)))-(1-(O12)),(N12)*(IF(AD12>0,AD12/100,100/ABS(AD12)))-(1-(N12))) | AZ12: =IF(BS12>=BT12,"OVER","UNDER") | BA12: =MAX(0,BS12,BT12) | BB12: =IF(BA12<=0,"PASS",IF(BA12<0.02,"PASS",IF(BA12<0.04,"LEAN",IF(BA12<0.07,"SMALL",IF(BA12<0.10,"MEDIUM","STRONG"))))) | BC12: =IF(BA12<0.01,1,IF(BA12<0.02,2,IF(BA12<0.03,3,IF(BA12<0.04,4,IF(BA12<0.05,5,IF(BA12<0.06,6,IF(BA12<0.07,7,IF(BA12<0.08,8,IF(BA12<0.10,9,10))))))))) | BD12: =IF(AZ12="OVER",(BO12)*(IF(AG12>0,AG12/100,100/ABS(AG12)))-(1-(BO12)),(BP12)*(IF(AH12>0,AH12/100,100/ABS(AH12)))-(1-(BP12))) | BE12: =R12 | BF12: =IF(OR(ISBLANK(T12),ISBLANK(V12)),13,(V12-T12)/(2.56310313109)) | BG12: =IF(OR(ISNA(BF12),BF12<=0,ISBLANK(AB12)),NA(),1-NORMSDIST(((-AB12)-(BE12))/(BF12))) | BH12: =IF(OR(ISNA(BF12),BF12<=0,ISBLANK(Z12)),NA(),NORMSDIST(((Z12)-(BE12))/(BF12))) | BI12: =IF(OR(ISBLANK(AC12),AC12=0),NA(),IF(AC12>0,100/(AC12+100),-(AC12)/(-(AC12)+100))) | BJ12: =IF(OR(ISBLANK(AA12),AA12=0),NA(),IF(AA12>0,100/(AA12+100),-(AA12)/(-(AA12)+100))) | BK12: =BG12-BI12 | BL12: =BH12-BJ12 | BM12: =S12 | BN12: =IF(OR(ISBLANK(W12),ISBLANK(Y12)),16,(Y12-W12)/(2.56310313109)) | BO12: =IF(OR(ISNA(BN12),BN12<=0,ISBLANK(AF12)),NA(),1-NORMSDIST(((AF12)-(BM12))/(BN12))) | BP12: =IF(ISNA(BO12),NA(),1-(BO12)) | BQ12: =IF(OR(ISBLANK(AG12),AG12=0),NA(),IF(AG12>0,100/(AG12+100),-(AG12)/(-(AG12)+100))) | BR12: =IF(OR(ISBLANK(AH12),AH12=0),NA(),IF(AH12>0,100/(AH12+100),-(AH12)/(-(AH12)+100))) | BS12: =BO12-BQ12 | BT12: =BP12-BR12
A13: 2026 | B13: 1 | C13: 2026-09-13 | D13: 16:25 | E13: 46278.684 | F13: 2026_01_GB_MIN | G13: GB | H13: MIN | I13: 1.5 | J13: -1.5 | K13: 100 | L13: -120 | M13: 46.5 | N13: 0.63 | O13: 0.37 | P13: 23.2 | Q13: 20.9 | R13: -2.3 | S13: 44.1 | T13: -16.6 | U13: -0.3 | V13: 16.4 | W13: 29.7 | X13: 43.7 | Y13: 61.8 | Z13: 1.5 | AA13: -110 | AB13: =-Z13 | AC13: -110 | AD13: 100 | AE13: -120 | AF13: 46.5 | AG13: -110 | AH13: -110 | AI13: =IF(OR(ISBLANK(AB13),ISBLANK(R13)),NA(),R13+AB13) | AJ13: =IF(OR(ISBLANK(AD13),AD13=0),NA(),IF(AD13>0,100/(AD13+100),-(AD13)/(-(AD13)+100))) | AK13: =IF(OR(ISBLANK(AE13),AE13=0),NA(),IF(AE13>0,100/(AE13+100),-(AE13)/(-(AE13)+100))) | AL13: =IF(OR(ISNA(AK13),ISNA(AJ13)),NA(),AJ13/(AK13+AJ13)) | AM13: =IF(OR(ISNA(AK13),ISNA(AJ13)),NA(),AK13/(AK13+AJ13)) | AN13: =N13-AL13 | AO13: =O13-AM13 | AP13: =IF(BK13>=BL13,H13,G13) | AQ13: =MAX(0,BK13,BL13) | AR13: =IF(AQ13<=0,"PASS",IF(AQ13<0.02,"PASS",IF(AQ13<0.04,"LEAN",IF(AQ13<0.07,"SMALL",IF(AQ13<0.10,"MEDIUM","STRONG"))))) | AS13: =IF(AQ13<0.01,1,IF(AQ13<0.02,2,IF(AQ13<0.03,3,IF(AQ13<0.04,4,IF(AQ13<0.05,5,IF(AQ13<0.06,6,IF(AQ13<0.07,7,IF(AQ13<0.08,8,IF(AQ13<0.10,9,10))))))))) | AT13: =IF(AP13=H13,(BG13)*(IF(AC13>0,AC13/100,100/ABS(AC13)))-(1-(BG13)),(BH13)*(IF(AA13>0,AA13/100,100/ABS(AA13)))-(1-(BH13))) | AU13: =IF((O13-AK13)>=(N13-AJ13),H13,G13) | AV13: =MAX(0,(O13-AK13),(N13-AJ13)) | AW13: =IF(AV13<=0,"PASS",IF(AV13<0.02,"PASS",IF(AV13<0.04,"LEAN",IF(AV13<0.07,"SMALL",IF(AV13<0.10,"MEDIUM","STRONG"))))) | AX13: =IF(AV13<0.01,1,IF(AV13<0.02,2,IF(AV13<0.03,3,IF(AV13<0.04,4,IF(AV13<0.05,5,IF(AV13<0.06,6,IF(AV13<0.07,7,IF(AV13<0.08,8,IF(AV13<0.10,9,10))))))))) | AY13: =IF(AU13=H13,(O13)*(IF(AE13>0,AE13/100,100/ABS(AE13)))-(1-(O13)),(N13)*(IF(AD13>0,AD13/100,100/ABS(AD13)))-(1-(N13))) | AZ13: =IF(BS13>=BT13,"OVER","UNDER") | BA13: =MAX(0,BS13,BT13) | BB13: =IF(BA13<=0,"PASS",IF(BA13<0.02,"PASS",IF(BA13<0.04,"LEAN",IF(BA13<0.07,"SMALL",IF(BA13<0.10,"MEDIUM","STRONG"))))) | BC13: =IF(BA13<0.01,1,IF(BA13<0.02,2,IF(BA13<0.03,3,IF(BA13<0.04,4,IF(BA13<0.05,5,IF(BA13<0.06,6,IF(BA13<0.07,7,IF(BA13<0.08,8,IF(BA13<0.10,9,10))))))))) | BD13: =IF(AZ13="OVER",(BO13)*(IF(AG13>0,AG13/100,100/ABS(AG13)))-(1-(BO13)),(BP13)*(IF(AH13>0,AH13/100,100/ABS(AH13)))-(1-(BP13))) | BE13: =R13 | BF13: =IF(OR(ISBLANK(T13),ISBLANK(V13)),13,(V13-T13)/(2.56310313109)) | BG13: =IF(OR(ISNA(BF13),BF13<=0,ISBLANK(AB13)),NA(),1-NORMSDIST(((-AB13)-(BE13))/(BF13))) | BH13: =IF(OR(ISNA(BF13),BF13<=0,ISBLANK(Z13)),NA(),NORMSDIST(((Z13)-(BE13))/(BF13))) | BI13: =IF(OR(ISBLANK(AC13),AC13=0),NA(),IF(AC13>0,100/(AC13+100),-(AC13)/(-(AC13)+100))) | BJ13: =IF(OR(ISBLANK(AA13),AA13=0),NA(),IF(AA13>0,100/(AA13+100),-(AA13)/(-(AA13)+100))) | BK13: =BG13-BI13 | BL13: =BH13-BJ13 | BM13: =S13 | BN13: =IF(OR(ISBLANK(W13),ISBLANK(Y13)),16,(Y13-W13)/(2.56310313109)) | BO13: =IF(OR(ISNA(BN13),BN13<=0,ISBLANK(AF13)),NA(),1-NORMSDIST(((AF13)-(BM13))/(BN13))) | BP13: =IF(ISNA(BO13),NA(),1-(BO13)) | BQ13: =IF(OR(ISBLANK(AG13),AG13=0),NA(),IF(AG13>0,100/(AG13+100),-(AG13)/(-(AG13)+100))) | BR13: =IF(OR(ISBLANK(AH13),AH13=0),NA(),IF(AH13>0,100/(AH13+100),-(AH13)/(-(AH13)+100))) | BS13: =BO13-BQ13 | BT13: =BP13-BR13
... A17: 2026 | B17: 1 | C17: 2026-09-14 | D17: 20:15 | E17: 46279.844 | F17: 2026_01_DEN_KC | G17: DEN | H17: KC | I17: 3 | J17: -3 | K17: 130 | L17: -155 | M17: 43.5 | N17: 0.5977 | O17: 0.4023 | P17: 22.8 | Q17: 21.2 | R17: -1.6 | S17: 44.1 | T17: -16.9 | U17: 0.5 | V17: 17.4 | W17: 28.5 | X17: 41.7 | Y17: 60.2 | Z17: 3 | AA17: -110 | AB17: =-Z17 | AC17: -110 | AD17: 130 | AE17: -155 | AF17: 43.5 | AG17: -110 | AH17: -110 | AI17: =IF(OR(ISBLANK(AB17),ISBLANK(R17)),NA(),R17+AB17) | AJ17: =IF(OR(ISBLANK(AD17),AD17=0),NA(),IF(AD17>0,100/(AD17+100),-(AD17)/(-(AD17)+100))) | AK17: =IF(OR(ISBLANK(AE17),AE17=0),NA(),IF(AE17>0,100/(AE17+100),-(AE17)/(-(AE17)+100))) | AL17: =IF(OR(ISNA(AK17),ISNA(AJ17)),NA(),AJ17/(AK17+AJ17)) | AM17: =IF(OR(ISNA(AK17),ISNA(AJ17)),NA(),AK17/(AK17+AJ17)) | AN17: =N17-AL17 | AO17: =O17-AM17 | AP17: =IF(BK17>=BL17,H17,G17) | AQ17: =MAX(0,BK17,BL17) | AR17: =IF(AQ17<=0,"PASS",IF(AQ17<0.02,"PASS",IF(AQ17<0.04,"LEAN",IF(AQ17<0.07,"SMALL",IF(AQ17<0.10,"MEDIUM","STRONG"))))) | AS17: =IF(AQ17<0.01,1,IF(AQ17<0.02,2,IF(AQ17<0.03,3,IF(AQ17<0.04,4,IF(AQ17<0.05,5,IF(AQ17<0.06,6,IF(AQ17<0.07,7,IF(AQ17<0.08,8,IF(AQ17<0.10,9,10))))))))) | AT17: =IF(AP17=H17,(BG17)*(IF(AC17>0,AC17/100,100/ABS(AC17)))-(1-(BG17)),(BH17)*(IF(AA17>0,AA17/100,100/ABS(AA17)))-(1-(BH17))) | AU17: =IF((O17-AK17)>=(N17-AJ17),H17,G17) | AV17: =MAX(0,(O17-AK17),(N17-AJ17)) | AW17: =IF(AV17<=0,"PASS",IF(AV17<0.02,"PASS",IF(AV17<0.04,"LEAN",IF(AV17<0.07,"SMALL",IF(AV17<0.10,"MEDIUM","STRONG"))))) | AX17: =IF(AV17<0.01,1,IF(AV17<0.02,2,IF(AV17<0.03,3,IF(AV17<0.04,4,IF(AV17<0.05,5,IF(AV17<0.06,6,IF(AV17<0.07,7,IF(AV17<0.08,8,IF(AV17<0.10,9,10))))))))) | AY17: =IF(AU17=H17,(O17)*(IF(AE17>0,AE17/100,100/ABS(AE17)))-(1-(O17)),(N17)*(IF(AD17>0,AD17/100,100/ABS(AD17)))-(1-(N17))) | AZ17: =IF(BS17>=BT17,"OVER","UNDER") | BA17: =MAX(0,BS17,BT17) | BB17: =IF(BA17<=0,"PASS",IF(BA17<0.02,"PASS",IF(BA17<0.04,"LEAN",IF(BA17<0.07,"SMALL",IF(BA17<0.10,"MEDIUM","STRONG"))))) | BC17: =IF(BA17<0.01,1,IF(BA17<0.02,2,IF(BA17<0.03,3,IF(BA17<0.04,4,IF(BA17<0.05,5,IF(BA17<0.06,6,IF(BA17<0.07,7,IF(BA17<0.08,8,IF(BA17<0.10,9,10))))))))) | BD17: =IF(AZ17="OVER",(BO17)*(IF(AG17>0,AG17/100,100/ABS(AG17)))-(1-(BO17)),(BP17)*(IF(AH17>0,AH17/100,100/ABS(AH17)))-(1-(BP17))) | BE17: =R17 | BF17: =IF(OR(ISBLANK(T17),ISBLANK(V17)),13,(V17-T17)/(2.56310313109)) | BG17: =IF(OR(ISNA(BF17),BF17<=0,ISBLANK(AB17)),NA(),1-NORMSDIST(((-AB17)-(BE17))/(BF17))) | BH17: =IF(OR(ISNA(BF17),BF17<=0,ISBLANK(Z17)),NA(),NORMSDIST(((Z17)-(BE17))/(BF17))) | BI17: =IF(OR(ISBLANK(AC17),AC17=0),NA(),IF(AC17>0,100/(AC17+100),-(AC17)/(-(AC17)+100))) | BJ17: =IF(OR(ISBLANK(AA17),AA17=0),NA(),IF(AA17>0,100/(AA17+100),-(AA17)/(-(AA17)+100))) | BK17: =BG17-BI17 | BL17: =BH17-BJ17 | BM17: =S17 | BN17: =IF(OR(ISBLANK(W17),ISBLANK(Y17)),16,(Y17-W17)/(2.56310313109)) | BO17: =IF(OR(ISNA(BN17),BN17<=0,ISBLANK(AF17)),NA(),1-NORMSDIST(((AF17)-(BM17))/(BN17))) | BP17: =IF(ISNA(BO17),NA(),1-(BO17)) | BQ17: =IF(OR(ISBLANK(AG17),AG17=0),NA(),IF(AG17>0,100/(AG17+100),-(AG17)/(-(AG17)+100))) | BR17: =IF(OR(ISBLANK(AH17),AH17=0),NA(),IF(AH17>0,100/(AH17+100),-(AH17)/(-(AH17)+100))) | BS17: =BO17-BQ17 | BT17: =BP17-BR17

Sheet Live
A1: season | B1: week | C1: date | D1: gametime | E1: game_datetime | F1: game_id | G1: away_abbr | H1: home_abbr | I1: quarter | J1: minutes_remaining_in_quarter | K1: minutes_remaining | L1: away_score_live | M1: home_score_live | N1: current_margin | O1: current_total | P1: w_time | Q1: pregame_mu_margin | R1: pregame_sigma_margin | S1: live_mu_margin | T1: live_sigma_margin | U1: live_away_win_prob | V1: live_home_win_prob | W1: away_spread_live | X1: away_spread_odds_live | Y1: home_spread_live | Z1: home_spread_odds_live | AA1: away_moneyline_live | AB1: home_moneyline_live | AC1: total_live | AD1: total_over_odds_live | AE1: total_under_odds_live | AF1: live_p_away_cover | AG1: live_p_home_cover | AH1: live_spread_value_side | AI1: live_spread_edge_prob | AJ1: live_spread_action | AK1: live_spread_confidence_1_10 | AL1: live_spread_ev | AM1: live_money_value_side | AN1: live_money_edge_prob | AO1: live_money_action | AP1: live_money_confidence_1_10 | AQ1: live_moneyline_ev | AR1: pregame_mu_total | AS1: pregame_sigma_total | AT1: live_mu_total | AU1: live_sigma_total | AV1: live_p_over | AW1: live_p_under | AX1: live_total_value_side | AY1: live_total_edge_prob | AZ1: live_total_action | BA1: live_total_confidence_1_10 | BB1: live_total_ev | BC1: live_spread_implied_away_prob | BD1: live_spread_implied_home_prob | BE1: live_spread_edge_away | BF1: live_spread_edge_home | BG1: live_total_implied_over_prob | BH1: live_total_implied_under_prob | BI1: live_total_edge_over | BJ1: live_total_edge_under
A2: ='Bets'!A2 | B2: ='Bets'!B2 | C2: ='Bets'!C2 | D2: ='Bets'!D2 | E2: ='Bets'!E2 | F2: ='Bets'!F2 | G2: ='Bets'!G2 | H2: ='Bets'!H2 | I2: 1 | J2: 15 | K2: =IF(OR(ISBLANK(I2),ISBLANK(J2)),NA(),MAX(0,MIN(60,(4-(I2))*15+(J2)))) | L2: 0 | M2: 0 | N2: =IF(OR(ISBLANK(M2),ISBLANK(L2)),NA(),M2-L2) | O2: =IF(OR(ISBLANK(M2),ISBLANK(L2)),NA(),M2+L2) | P2: =IF(ISBLANK(K2),NA(),MAX(0,MIN(1,K2/60))) | Q2: ='Bets'!R2 | R2: =IF(OR(ISBLANK('Bets'!T2),ISBLANK('Bets'!V2)),13,('Bets'!V2-'Bets'!T2)/(2.56310313109)) | S2: =IF(OR(ISNA(P2),ISNA(N2)),NA(),(P2)*(Q2)+(1-(P2))*(N2)) | T2: =IF(OR(ISNA(P2),ISBLANK(R2)),NA(),(R2)*SQRT(P2)) | U2: =IF(ISNA(V2),NA(),1-(V2)) | V2: =IF(ISNA(P2),NA(),IF(P2>=0.999999,'Bets'!O2,IF(OR(ISNA(T2),T2<=0),NA(),1-NORMSDIST((0-(S2))/(T2))))) | W2: 3 | X2: -110 | Y2: =-W2 | Z2: -110 | AA2: 140 | AB2: -166 | AC2: 44.5 | AD2: -110 | AE2: -110 | AF2: =IF(OR(ISNA(T2),T2<=0,ISBLANK(W2)),NA(),NORMSDIST(((W2)-(S2))/(T2))) | AG2: =IF(OR(ISNA(T2),T2<=0,ISBLANK(Y2)),NA(),1-NORMSDIST(((-Y2)-(S2))/(T2))) | AH2: =IF(BF2>=BE2,H2,G2) | AI2: =MAX(0,BF2,BE2) | AJ2: =IF(AI2<=0,"PASS",IF(AI2<0.02,"PASS",IF(AI2<0.04,"LEAN",IF(AI2<0.07,"SMALL",IF(AI2<0.10,"MEDIUM","STRONG"))))) | AK2: =IF(AI2<0.01,1,IF(AI2<0.02,2,IF(AI2<0.03,3,IF(AI2<0.04,4,IF(AI2<0.05,5,IF(AI2<0.06,6,IF(AI2<0.07,7,IF(AI2<0.08,8,IF(AI2<0.10,9,10))))))))) | AL2: =IF(AH2=H2,(AG2)*(IF(Z2>0,Z2/100,100/ABS(Z2)))-(1-(AG2)),(AF2)*(IF(X2>0,X2/100,100/ABS(X2)))-(1-(AF2))) | AM2: =IF((V2)-(IF(OR(ISBLANK(AB2),AB2=0),NA(),IF(AB2>0,100/(AB2+100),-(AB2)/(-(AB2)+100))))>=(U2)-(IF(OR(ISBLANK(AA2),AA2=0),NA(),IF(AA2>0,100/(AA2+100),-(AA2)/(-(AA2)+100)))),H2,G2) | AN2: =MAX(0,(V2)-(IF(OR(ISBLANK(AB2),AB2=0),NA(),IF(AB2>0,100/(AB2+100),-(AB2)/(-(AB2)+100)))),(U2)-(IF(OR(ISBLANK(AA2),AA2=0),NA(),IF(AA2>0,100/(AA2+100),-(AA2)/(-(AA2)+100))))) | AO2: =IF(AN2<=0,"PASS",IF(AN2<0.02,"PASS",IF(AN2<0.04,"LEAN",IF(AN2<0.07,"SMALL",IF(AN2<0.10,"MEDIUM","STRONG"))))) | AP2: =IF(AN2<0.01,1,IF(AN2<0.02,2,IF(AN2<0.03,3,IF(AN2<0.04,4,IF(AN2<0.05,5,IF(AN2<0.06,6,IF(AN2<0.07,7,IF(AN2<0.08,8,IF(AN2<0.10,9,10))))))))) | AQ2: =IF(AM2=H2,(V2)*(IF(AB2>0,AB2/100,100/ABS(AB2)))-(1-(V2)),(U2)*(IF(AA2>0,AA2/100,100/ABS(AA2)))-(1-(U2))) | AR2: ='Bets'!S2 | AS2: =IF(OR(ISBLANK('Bets'!W2),ISBLANK('Bets'!Y2)),16,('Bets'!Y2-'Bets'!W2)/(2.56310313109)) | AT2: =IF(OR(ISNA(P2),ISNA(O2)),NA(),(P2)*(AR2)+(1-(P2))*(O2)) | AU2: =IF(OR(ISNA(P2),ISBLANK(AS2)),NA(),(AS2)*SQRT(P2)) | AV2: =IF(OR(ISNA(AU2),AU2<=0,ISBLANK(AC2)),NA(),1-NORMSDIST(((AC2)-(AT2))/(AU2))) | AW2: =IF(ISNA(AV2),NA(),1-(AV2)) | AX2: =IF(BI2>=BJ2,"OVER","UNDER") | AY2: =MAX(0,BI2,BJ2) | AZ2: =IF(AY2<=0,"PASS",IF(AY2<0.02,"PASS",IF(AY2<0.04,"LEAN",IF(AY2<0.07,"SMALL",IF(AY2<0.10,"MEDIUM","STRONG"))))) | BA2: =IF(AY2<0.01,1,IF(AY2<0.02,2,IF(AY2<0.03,3,IF(AY2<0.04,4,IF(AY2<0.05,5,IF(AY2<0.06,6,IF(AY2<0.07,7,IF(AY2<0.08,8,IF(AY2<0.10,9,10))))))))) | BB2: =IF(AX2="OVER",(AV2)*(IF(AD2>0,AD2/100,100/ABS(AD2)))-(1-(AV2)),(AW2)*(IF(AE2>0,AE2/100,100/ABS(AE2)))-(1-(AW2))) | BC2: =IF(OR(ISBLANK(X2),X2=0),NA(),IF(X2>0,100/(X2+100),-(X2)/(-(X2)+100))) | BD2: =IF(OR(ISBLANK(Z2),Z2=0),NA(),IF(Z2>0,100/(Z2+100),-(Z2)/(-(Z2)+100))) | BE2: =AF2-BC2 | BF2: =AG2-BD2 | BG2: =IF(OR(ISBLANK(AD2),AD2=0),NA(),IF(AD2>0,100/(AD2+100),-(AD2)/(-(AD2)+100))) | BH2: =IF(OR(ISBLANK(AE2),AE2=0),NA(),IF(AE2>0,100/(AE2+100),-(AE2)/(-(AE2)+100))) | BI2: =AV2-BG2 | BJ2: =AW2-BH2
A3: ='Bets'!A3 | B3: ='Bets'!B3 | C3: ='Bets'!C3 | D3: ='Bets'!D3 | E3: ='Bets'!E3 | F3: ='Bets'!F3 | G3: ='Bets'!G3 | H3: ='Bets'!H3 | I3: 1 | J3: 15 | K3: =IF(OR(ISBLANK(I3),ISBLANK(J3)),NA(),MAX(0,MIN(60,(4-(I3))*15+(J3)))) | L3: 0 | M3: 0 | N3: =IF(OR(ISBLANK(M3),ISBLANK(L3)),NA(),M3-L3) | O3: =IF(OR(ISBLANK(M3),ISBLANK(L3)),NA(),M3+L3) | P3: =IF(ISBLANK(K3),NA(),MAX(0,MIN(1,K3/60))) | Q3: ='Bets'!R3 | R3: =IF(OR(ISBLANK('Bets'!T3),ISBLANK('Bets'!V3)),13,('Bets'!V3-'Bets'!T3)/(2.56310313109)) | S3: =IF(OR(ISNA(P3),ISNA(N3)),NA(),(P3)*(Q3)+(1-(P3))*(N3)) | T3: =IF(OR(ISNA(P3),ISBLANK(R3)),NA(),(R3)*SQRT(P3)) | U3: =IF(ISNA(V3),NA(),1-(V3)) | V3: =IF(ISNA(P3),NA(),IF(P3>=0.999999,'Bets'!O3,IF(OR(ISNA(T3),T3<=0),NA(),1-NORMSDIST((0-(S3))/(T3))))) | W3: 3.5 | X3: -110 | Y3: =-W3 | Z3: -110 | AA3: 164 | AB3: -198 | AC3: 48.5 | AD3: -110 | AE3: -110 | AF3: =IF(OR(ISNA(T3),T3<=0,ISBLANK(W3)),NA(),NORMSDIST(((W3)-(S3))/(T3))) | AG3: =IF(OR(ISNA(T3),T3<=0,ISBLANK(Y3)),NA(),1-NORMSDIST(((-Y3)-(S3))/(T3))) | AH3: =IF(BF3>=BE3,H3,G3) | AI3: =MAX(0,BF3,BE3) | AJ3: =IF(AI3<=0,"PASS",IF(AI3<0.02,"PASS",IF(AI3<0.04,"LEAN",IF(AI3<0.07,"SMALL",IF(AI3<0.10,"MEDIUM","STRONG"))))) | AK3: =IF(AI3<0.01,1,IF(AI3<0.02,2,IF(AI3<0.03,3,IF(AI3<0.04,4,IF(AI3<0.05,5,IF(AI3<0.06,6,IF(AI3<0.07,7,IF(AI3<0.08,8,IF(AI3<0.10,9,10))))))))) | AL3: =IF(AH3=H3,(AG3)*(IF(Z3>0,Z3/100,100/ABS(Z3)))-(1-(AG3)),(AF3)*(IF(X3>0,X3/100,100/ABS(X3)))-(1-(AF3))) | AM3: =IF((V3)-(IF(OR(ISBLANK(AB3),AB3=0),NA(),IF(AB3>0,100/(AB3+100),-(AB3)/(-(AB3)+100))))>=(U3)-(IF(OR(ISBLANK(AA3),AA3=0),NA(),IF(AA3>0,100/(AA3+100),-(AA3)/(-(AA3)+100)))),H3,G3) | AN3: =MAX(0,(V3)-(IF(OR(ISBLANK(AB3),AB3=0),NA(),IF(AB3>0,100/(AB3+100),-(AB3)/(-(AB3)+100)))),(U3)-(IF(OR(ISBLANK(AA3),AA3=0),NA(),IF(AA3>0,100/(AA3+100),-(AA3)/(-(AA3)+100))))) | AO3: =IF(AN3<=0,"PASS",IF(AN3<0.02,"PASS",IF(AN3<0.04,"LEAN",IF(AN3<0.07,"SMALL",IF(AN3<0.10,"MEDIUM","STRONG"))))) | AP3: =IF(AN3<0.01,1,IF(AN3<0.02,2,IF(AN3<0.03,3,IF(AN3<0.04,4,IF(AN3<0.05,5,IF(AN3<0.06,6,IF(AN3<0.07,7,IF(AN3<0.08,8,IF(AN3<0.10,9,10))))))))) | AQ3: =IF(AM3=H3,(V3)*(IF(AB3>0,AB3/100,100/ABS(AB3)))-(1-(V3)),(U3)*(IF(AA3>0,AA3/100,100/ABS(AA3)))-(1-(U3))) | AR3: ='Bets'!S3 | AS3: =IF(OR(ISBLANK('Bets'!W3),ISBLANK('Bets'!Y3)),16,('Bets'!Y3-'Bets'!W3)/(2.56310313109)) | AT3: =IF(OR(ISNA(P3),ISNA(O3)),NA(),(P3)*(AR3)+(1-(P3))*(O3)) | AU3: =IF(OR(ISNA(P3),ISBLANK(AS3)),NA(),(AS3)*SQRT(P3)) | AV3: =IF(OR(ISNA(AU3),AU3<=0,ISBLANK(AC3)),NA(),1-NORMSDIST(((AC3)-(AT3))/(AU3))) | AW3: =IF(ISNA(AV3),NA(),1-(AV3)) | AX3: =IF(BI3>=BJ3,"OVER","UNDER") | AY3: =MAX(0,BI3,BJ3) | AZ3: =IF(AY3<=0,"PASS",IF(AY3<0.02,"PASS",IF(AY3<0.04,"LEAN",IF(AY3<0.07,"SMALL",IF(AY3<0.10,"MEDIUM","STRONG"))))) | BA3: =IF(AY3<0.01,1,IF(AY3<0.02,2,IF(AY3<0.03,3,IF(AY3<0.04,4,IF(AY3<0.05,5,IF(AY3<0.06,6,IF(AY3<0.07,7,IF(AY3<0.08,8,IF(AY3<0.10,9,10))))))))) | BB3: =IF(AX3="OVER",(AV3)*(IF(AD3>0,AD3/100,100/ABS(AD3)))-(1-(AV3)),(AW3)*(IF(AE3>0,AE3/100,100/ABS(AE3)))-(1-(AW3))) | BC3: =IF(OR(ISBLANK(X3),X3=0),NA(),IF(X3>0,100/(X3+100),-(X3)/(-(X3)+100))) | BD3: =IF(OR(ISBLANK(Z3),Z3=0),NA(),IF(Z3>0,100/(Z3+100),-(Z3)/(-(Z3)+100))) | BE3: =AF3-BC3 | BF3: =AG3-BD3 | BG3: =IF(OR(ISBLANK(AD3),AD3=0),NA(),IF(AD3>0,100/(AD3+100),-(AD3)/(-(AD3)+100))) | BH3: =IF(OR(ISBLANK(AE3),AE3=0),NA(),IF(AE3>0,100/(AE3+100),-(AE3)/(-(AE3)+100))) | BI3: =AV3-BG3 | BJ3: =AW3-BH3
A4: ='Bets'!A4 | B4: ='Bets'!B4 | C4: ='Bets'!C4 | D4: ='Bets'!D4 | E4: ='Bets'!E4 | F4: ='Bets'!F4 | G4: ='Bets'!G4 | H4: ='Bets'!H4 | I4: 1 | J4: 15 | K4: =IF(OR(ISBLANK(I4),ISBLANK(J4)),NA(),MAX(0,MIN(60,(4-(I4))*15+(J4)))) | L4: 0 | M4: 0 | N4: =IF(OR(ISBLANK(M4),ISBLANK(L4)),NA(),M4-L4) | O4: =IF(OR(ISBLANK(M4),ISBLANK(L4)),NA(),M4+L4) | P4: =IF(ISBLANK(K4),NA(),MAX(0,MIN(1,K4/60))) | Q4: ='Bets'!R4 | R4: =IF(OR(ISBLANK('Bets'!T4),ISBLANK('Bets'!V4)),13,('Bets'!V4-'Bets'!T4)/(2.56310313109)) | S4: =IF(OR(ISNA(P4),ISNA(N4)),NA(),(P4)*(Q4)+(1-(P4))*(N4)) | T4: =IF(OR(ISNA(P4),ISBLANK(R4)),NA(),(R4)*SQRT(P4)) | U4: =IF(ISNA(V4),NA(),1-(V4)) | V4: =IF(ISNA(P4),NA(),IF(P4>=0.999999,'Bets'!O4,IF(OR(ISNA(T4),T4<=0),NA(),1-NORMSDIST((0-(S4))/(T4))))) | W4: 3.5 | X4: -110 | Y4: =-W4 | Z4: -110 | AA4: 154 | AB4: -185 | AC4: 42.5 | AD4: -110 | AE4: -110 | AF4: =IF(OR(ISNA(T4),T4<=0,ISBLANK(W4)),NA(),NORMSDIST(((W4)-(S4))/(T4))) | AG4: =IF(OR(ISNA(T4),T4<=0,ISBLANK(Y4)),NA(),1-NORMSDIST(((-Y4)-(S4))/(T4))) | AH4: =IF(BF4>=BE4,H4,G4) | AI4: =MAX(0,BF4,BE4) | AJ4: =IF(AI4<=0,"PASS",IF(AI4<0.02,"PASS",IF(AI4<0.04,"LEAN",IF(AI4<0.07,"SMALL",IF(AI4<0.10,"MEDIUM","STRONG"))))) | AK4: =IF(AI4<0.01,1,IF(AI4<0.02,2,IF(AI4<0.03,3,IF(AI4<0.04,4,IF(AI4<0.05,5,IF(AI4<0.06,6,IF(AI4<0.07,7,IF(AI4<0.08,8,IF(AI4<0.10,9,10))))))))) | AL4: =IF(AH4=H4,(AG4)*(IF(Z4>0,Z4/100,100/ABS(Z4)))-(1-(AG4)),(AF4)*(IF(X4>0,X4/100,100/ABS(X4)))-(1-(AF4))) | AM4: =IF((V4)-(IF(OR(ISBLANK(AB4),AB4=0),NA(),IF(AB4>0,100/(AB4+100),-(AB4)/(-(AB4)+100))))>=(U4)-(IF(OR(ISBLANK(AA4),AA4=0),NA(),IF(AA4>0,100/(AA4+100),-(AA4)/(-(AA4)+100)))),H4,G4) | AN4: =MAX(0,(V4)-(IF(OR(ISBLANK(AB4),AB4=0),NA(),IF(AB4>0,100/(AB4+100),-(AB4)/(-(AB4)+100)))),(U4)-(IF(OR(ISBLANK(AA4),AA4=0),NA(),IF(AA4>0,100/(AA4+100),-(AA4)/(-(AA4)+100))))) | AO4: =IF(AN4<=0,"PASS",IF(AN4<0.02,"PASS",IF(AN4<0.04,"LEAN",IF(AN4<0.07,"SMALL",IF(AN4<0.10,"MEDIUM","STRONG"))))) | AP4: =IF(AN4<0.01,1,IF(AN4<0.02,2,IF(AN4<0.03,3,IF(AN4<0.04,4,IF(AN4<0.05,5,IF(AN4<0.06,6,IF(AN4<0.07,7,IF(AN4<0.08,8,IF(AN4<0.10,9,10))))))))) | AQ4: =IF(AM4=H4,(V4)*(IF(AB4>0,AB4/100,100/ABS(AB4)))-(1-(V4)),(U4)*(IF(AA4>0,AA4/100,100/ABS(AA4)))-(1-(U4))) | AR4: ='Bets'!S4 | AS4: =IF(OR(ISBLANK('Bets'!W4),ISBLANK('Bets'!Y4)),16,('Bets'!Y4-'Bets'!W4)/(2.56310313109)) | AT4: =IF(OR(ISNA(P4),ISNA(O4)),NA(),(P4)*(AR4)+(1-(P4))*(O4)) | AU4: =IF(OR(ISNA(P4),ISBLANK(AS4)),NA(),(AS4)*SQRT(P4)) | AV4: =IF(OR(ISNA(AU4),AU4<=0,ISBLANK(AC4)),NA(),1-NORMSDIST(((AC4)-(AT4))/(AU4))) | AW4: =IF(ISNA(AV4),NA(),1-(AV4)) | AX4: =IF(BI4>=BJ4,"OVER","UNDER") | AY4: =MAX(0,BI4,BJ4) | AZ4: =IF(AY4<=0,"PASS",IF(AY4<0.02,"PASS",IF(AY4<0.04,"LEAN",IF(AY4<0.07,"SMALL",IF(AY4<0.10,"MEDIUM","STRONG"))))) | BA4: =IF(AY4<0.01,1,IF(AY4<0.02,2,IF(AY4<0.03,3,IF(AY4<0.04,4,IF(AY4<0.05,5,IF(AY4<0.06,6,IF(AY4<0.07,7,IF(AY4<0.08,8,IF(AY4<0.10,9,10))))))))) | BB4: =IF(AX4="OVER",(AV4)*(IF(AD4>0,AD4/100,100/ABS(AD4)))-(1-(AV4)),(AW4)*(IF(AE4>0,AE4/100,100/ABS(AE4)))-(1-(AW4))) | BC4: =IF(OR(ISBLANK(X4),X4=0),NA(),IF(X4>0,100/(X4+100),-(X4)/(-(X4)+100))) | BD4: =IF(OR(ISBLANK(Z4),Z4=0),NA(),IF(Z4>0,100/(Z4+100),-(Z4)/(-(Z4)+100))) | BE4: =AF4-BC4 | BF4: =AG4-BD4 | BG4: =IF(OR(ISBLANK(AD4),AD4=0),NA(),IF(AD4>0,100/(AD4+100),-(AD4)/(-(AD4)+100))) | BH4: =IF(OR(ISBLANK(AE4),AE4=0),NA(),IF(AE4>0,100/(AE4+100),-(AE4)/(-(AE4)+100))) | BI4: =AV4-BG4 | BJ4: =AW4-BH4
A5: ='Bets'!A5 | B5: ='Bets'!B5 | C5: ='Bets'!C5 | D5: ='Bets'!D5 | E5: ='Bets'!E5 | F5: ='Bets'!F5 | G5: ='Bets'!G5 | H5: ='Bets'!H5 | I5: 1 | J5: 15 | K5: =IF(OR(ISBLANK(I5),ISBLANK(J5)),NA(),MAX(0,MIN(60,(4-(I5))*15+(J5)))) | L5: 0 | M5: 0 | N5: =IF(OR(ISBLANK(M5),ISBLANK(L5)),NA(),M5-L5) | O5: =IF(OR(ISBLANK(M5),ISBLANK(L5)),NA(),M5+L5) | P5: =IF(ISBLANK(K5),NA(),MAX(0,MIN(1,K5/60))) | Q5: ='Bets'!R5 | R5: =IF(OR(ISBLANK('Bets'!T5),ISBLANK('Bets'!V5)),13,('Bets'!V5-'Bets'!T5)/(2.56310313109)) | S5: =IF(OR(ISNA(P5),ISNA(N5)),NA(),(P5)*(Q5)+(1-(P5))*(N5)) | T5: =IF(OR(ISNA(P5),ISBLANK(R5)),NA(),(R5)*SQRT(P5)) | U5: =IF(ISNA(V5),NA(),1-(V5)) | V5: =IF(ISNA(P5),NA(),IF(P5>=0.999999,'Bets'!O5,IF(OR(ISNA(T5),T5<=0),NA(),1-NORMSDIST((0-(S5))/(T5))))) | W5: -3.5 | X5: -110 | Y5: =-W5 | Z5: -110 | AA5: -175 | AB5: 145 | AC5: 47.5 | AD5: -110 | AE5: -110 | AF5: =IF(OR(ISNA(T5),T5<=0,ISBLANK(W5)),NA(),NORMSDIST(((W5)-(S5))/(T5))) | AG5: =IF(OR(ISNA(T5),T5<=0,ISBLANK(Y5)),NA(),1-NORMSDIST(((-Y5)-(S5))/(T5))) | AH5: =IF(BF5>=BE5,H5,G5) | AI5: =MAX(0,BF5,BE5) | AJ5: =IF(AI5<=0,"PASS",IF(AI5<0.02,"PASS",IF(AI5<0.04,"LEAN",IF(AI5<0.07,"SMALL",IF(AI5<0.10,"MEDIUM","STRONG"))))) | AK5: =IF(AI5<0.01,1,IF(AI5<0.02,2,IF(AI5<0.03,3,IF(AI5<0.04,4,IF(AI5<0.05,5,IF(AI5<0.06,6,IF(AI5<0.07,7,IF(AI5<0.08,8,IF(AI5<0.10,9,10))))))))) | AL5: =IF(AH5=H5,(AG5)*(IF(Z5>0,Z5/100,100/ABS(Z5)))-(1-(AG5)),(AF5)*(IF(X5>0,X5/100,100/ABS(X5)))-(1-(AF5))) | AM5: =IF((V5)-(IF(OR(ISBLANK(AB5),AB5=0),NA(),IF(AB5>0,100/(AB5+100),-(AB5)/(-(AB5)+100))))>=(U5)-(IF(OR(ISBLANK(AA5),AA5=0),NA(),IF(AA5>0,100/(AA5+100),-(AA5)/(-(AA5)+100)))),H5,G5) | AN5: =MAX(0,(V5)-(IF(OR(ISBLANK(AB5),AB5=0),NA(),IF(AB5>0,100/(AB5+100),-(AB5)/(-(AB5)+100)))),(U5)-(IF(OR(ISBLANK(AA5),AA5=0),NA(),IF(AA5>0,100/(AA5+100),-(AA5)/(-(AA5)+100))))) | AO5: =IF(AN5<=0,"PASS",IF(AN5<0.02,"PASS",IF(AN5<0.04,"LEAN",IF(AN5<0.07,"SMALL",IF(AN5<0.10,"MEDIUM","STRONG"))))) | AP5: =IF(AN5<0.01,1,IF(AN5<0.02,2,IF(AN5<0.03,3,IF(AN5<0.04,4,IF(AN5<0.05,5,IF(AN5<0.06,6,IF(AN5<0.07,7,IF(AN5<0.08,8,IF(AN5<0.10,9,10))))))))) | AQ5: =IF(AM5=H5,(V5)*(IF(AB5>0,AB5/100,100/ABS(AB5)))-(1-(V5)),(U5)*(IF(AA5>0,AA5/100,100/ABS(AA5)))-(1-(U5))) | AR5: ='Bets'!S5 | AS5: =IF(OR(ISBLANK('Bets'!W5),ISBLANK('Bets'!Y5)),16,('Bets'!Y5-'Bets'!W5)/(2.56310313109)) | AT5: =IF(OR(ISNA(P5),ISNA(O5)),NA(),(P5)*(AR5)+(1-(P5))*(O5)) | AU5: =IF(OR(ISNA(P5),ISBLANK(AS5)),NA(),(AS5)*SQRT(P5)) | AV5: =IF(OR(ISNA(AU5),AU5<=0,ISBLANK(AC5)),NA(),1-NORMSDIST(((AC5)-(AT5))/(AU5))) | AW5: =IF(ISNA(AV5),NA(),1-(AV5)) | AX5: =IF(BI5>=BJ5,"OVER","UNDER") | AY5: =MAX(0,BI5,BJ5) | AZ5: =IF(AY5<=0,"PASS",IF(AY5<0.02,"PASS",IF(AY5<0.04,"LEAN",IF(AY5<0.07,"SMALL",IF(AY5<0.10,"MEDIUM","STRONG"))))) | BA5: =IF(AY5<0.01,1,IF(AY5<0.02,2,IF(AY5<0.03,3,IF(AY5<0.04,4,IF(AY5<0.05,5,IF(AY5<0.06,6,IF(AY5<0.07,7,IF(AY5<0.08,8,IF(AY5<0.10,9,10))))))))) | BB5: =IF(AX5="OVER",(AV5)*(IF(AD5>0,AD5/100,100/ABS(AD5)))-(1-(AV5)),(AW5)*(IF(AE5>0,AE5/100,100/ABS(AE5)))-(1-(AW5))) | BC5: =IF(OR(ISBLANK(X5),X5=0),NA(),IF(X5>0,100/(X5+100),-(X5)/(-(X5)+100))) | BD5: =IF(OR(ISBLANK(Z5),Z5=0),NA(),IF(Z5>0,100/(Z5+100),-(Z5)/(-(Z5)+100))) | BE5: =AF5-BC5 | BF5: =AG5-BD5 | BG5: =IF(OR(ISBLANK(AD5),AD5=0),NA(),IF(AD5>0,100/(AD5+100),-(AD5)/(-(AD5)+100))) | BH5: =IF(OR(ISBLANK(AE5),AE5=0),NA(),IF(AE5>0,100/(AE5+100),-(AE5)/(-(AE5)+100))) | BI5: =AV5-BG5 | BJ5: =AW5-BH5
